Workbook

Sheet Introduction
A1: Configuration Baseline based on NIST SP 800-53 Rev. 5 (Release 5.2.0) with NIST CSF 2.0 Mapping
A2: Prefix ESBIT- is applied to every original NIST control identifier to form the new Control ID (for example AC-01 becomes ESBIT-AC-01). Sheets: Introduction, Config Baseline (main register), Summary.
A4: 1. Purpose of the Configuration Baseline
A5: This configuration baseline is established so that every cloud, network, database and infrastructure component is configured in accordance with a documented security baseline, giving the organization a consistent, repeatable and auditable way to harden its systems.
A6: It translates the NIST SP 800-53 Rev. 5 control catalog (20 families, base controls and control enhancements) into concrete configuration expectations, identifies which IT domain each control affects, and rates how strongly each control depends on technical configuration, so that administrators can prioritize what must be present in device and system configurations.
A7: The baseline supports: (1) a common security standard for all environments; (2) detection of configuration drift and unauthorized change; (3) evidence for internal audit and compliance reviews; and (4) alignment of technical settings with NIST CSF 2.0 outcomes.
A8: How to use the Config Baseline sheet: filter column K (IT domain) to select the technology in scope, filter column L to start with Level 1 items, read column I (English) or J (Thai) for the key configuration activity, then map each item to the vendor-specific setting (for example CIS Benchmark or STIG) for your platform.
A9: Important notes: the CSF 2.0 mapping and the Level rating are analyst-derived guidance for building the baseline and should be validated against the official NIST SP 800-53 to CSF 2.0 crosswalk and the organization's risk assessment. Withdrawn controls are excluded. Enhancement levels are derived from the base control (one level lower unless the enhancement concerns encryption, authentication, privilege, integrity, audit or deny-by-default).
A11: 2. The 20 NIST SP 800-53 Control Families and Their Relevance to the Configuration Baseline
A12: Control Family | B12: What it covers | C12: Relevance to the configuration baseline | D12: Typical configuration focus | E12: Rows in register | F12: of which Level 1
A13: AC - Access Control | B13: Who and what may access systems, data and networks, and how sessions and information flows are controlled. | C13: High - directly defines account, privilege, session, remote access and network flow settings. | D13: Account lockout, session timeout, least-privilege roles, VPN/remote access, firewall rules, login banner, wireless security. | E13: =COUNTIF('Config Baseline'!$C:$C,"Access Control (AC)") -> 127 | F13: =COUNTIFS('Config Baseline'!$C:$C,"Access Control (AC)",'Config Baseline'!$L:$L,"Level 1*") -> 22
A14: AT - Awareness and Training | B14: Security awareness and role-based training. | C14: Low - people/process control that supports correct configuration by trained administrators. | D14: Administrator and developer training on secure configuration. | E14: =COUNTIF('Config Baseline'!$C:$C,"Awareness and Training (AT)") -> 16 | F14: =COUNTIFS('Config Baseline'!$C:$C,"Awareness and Training (AT)",'Config Baseline'!$L:$L,"Level 1*") -> 0
A15: AU - Audit and Accountability | B15: Event logging, log content, protection, retention, time stamps and review. | C15: High - logging must be enabled and configured on every component. | D15: Enable logging, log format, NTP, central syslog/SIEM forwarding, retention, log integrity. | E15: =COUNTIF('Config Baseline'!$C:$C,"Audit and Accountability (AU)") -> 57 | F15: =COUNTIFS('Config Baseline'!$C:$C,"Audit and Accountability (AU)",'Config Baseline'!$L:$L,"Level 1*") -> 12
A16: CA - Assessment, Authorization, and Monitoring | B16: Control assessment, system interconnection, POA&M, continuous monitoring and penetration testing. | C16: Medium - drives compliance checking and monitoring of configuration. | D16: Configuration compliance scans, interconnection rules, drift monitoring. | E16: =COUNTIF('Config Baseline'!$C:$C,"Assessment, Authorization, and Monitoring (CA)") -> 25 | F16: =COUNTIFS('Config Baseline'!$C:$C,"Assessment, Authorization, and Monitoring (CA)",'Config Baseline'!$L:$L,"Level 1*") -> 0
A17: CM - Configuration Management | B17: Baseline configuration, change control, least functionality, software restrictions and inventory. | C17: Very high - the core of the configuration baseline. | D17: Hardened baselines (CIS/STIG), change control, disable unused services, allowlisting, asset inventory. | E17: =COUNTIF('Config Baseline'!$C:$C,"Configuration Management (CM)") -> 57 | F17: =COUNTIFS('Config Baseline'!$C:$C,"Configuration Management (CM)",'Config Baseline'!$L:$L,"Level 1*") -> 8
A18: CP - Contingency Planning | B18: Contingency planning, backup, alternate sites, telecommunications and recovery. | C18: Medium to high - backup, replication and failover settings. | D18: Backup jobs and encryption, replication, DR failover, redundant links. | E18: =COUNTIF('Config Baseline'!$C:$C,"Contingency Planning (CP)") -> 49 | F18: =COUNTIFS('Config Baseline'!$C:$C,"Contingency Planning (CP)",'Config Baseline'!$L:$L,"Level 1*") -> 3
A19: IA - Identification and Authentication | B19: Authentication of users, devices and services and management of authenticators. | C19: High - authentication settings on every platform. | D19: MFA, password policy, 802.1X/NAC, certificates, service identities, SSO. | E19: =COUNTIF('Config Baseline'!$C:$C,"Identification and Authentication (IA)") -> 61 | F19: =COUNTIFS('Config Baseline'!$C:$C,"Identification and Authentication (IA)",'Config Baseline'!$L:$L,"Level 1*") -> 7
A20: IR - Incident Response | B20: Incident handling capability, training, testing and reporting. | C20: Low to medium - mostly process, with tooling configuration for handling. | D20: SIEM/SOAR playbooks, containment actions, ticketing. | E20: =COUNTIF('Config Baseline'!$C:$C,"Incident Response (IR)") -> 39 | F20: =COUNTIFS('Config Baseline'!$C:$C,"Incident Response (IR)",'Config Baseline'!$L:$L,"Level 1*") -> 0
A21: MA - Maintenance | B21: Controlled and remote maintenance, maintenance tools and personnel. | C21: Low to medium - remote maintenance session settings. | D21: Vendor remote access with MFA, encryption, logging and session termination. | E21: =COUNTIF('Config Baseline'!$C:$C,"Maintenance (MA)") -> 28 | F21: =COUNTIFS('Config Baseline'!$C:$C,"Maintenance (MA)",'Config Baseline'!$L:$L,"Level 1*") -> 3
A22: MP - Media Protection | B22: Access, marking, storage, transport and sanitization of media. | C22: Low to medium - removable media and encryption settings. | D22: USB/removable media control, disk encryption, secure wipe. | E22: =COUNTIF('Config Baseline'!$C:$C,"Media Protection (MP)") -> 20 | F22: =COUNTIFS('Config Baseline'!$C:$C,"Media Protection (MP)",'Config Baseline'!$L:$L,"Level 1*") -> 0
A23: PE - Physical and Environmental Protection | B23: Physical access, monitoring, power, fire and environmental protection. | C23: Low - facility controls rather than IT configuration. | D23: Badge/CCTV systems, UPS, fire suppression, HVAC monitoring. | E23: =COUNTIF('Config Baseline'!$C:$C,"Physical and Environmental Protection (PE)") -> 50 | F23: =COUNTIFS('Config Baseline'!$C:$C,"Physical and Environmental Protection (PE)",'Config Baseline'!$L:$L,"Level 1*") -> 0
A24: PL - Planning | B24: Security planning, rules of behavior, security architecture and baseline selection. | C24: Medium - architecture and baseline tailoring drive the design. | D24: Zoning, defense in depth, segmentation, central management. | E24: =COUNTIF('Config Baseline'!$C:$C,"Planning (PL)") -> 11 | F24: =COUNTIFS('Config Baseline'!$C:$C,"Planning (PL)",'Config Baseline'!$L:$L,"Level 1*") -> 0
A25: PM - Program Management | B25: Enterprise security and privacy program management. | C25: Low - governance with no direct device configuration. | D25: Program plans, roles, metrics and risk strategy. | E25: =COUNTIF('Config Baseline'!$C:$C,"Program Management (PM)") -> 37 | F25: =COUNTIFS('Config Baseline'!$C:$C,"Program Management (PM)",'Config Baseline'!$L:$L,"Level 1*") -> 0
A26: PS - Personnel Security | B26: Personnel screening, termination, transfer and access agreements. | C26: Low - process, with account de-provisioning settings. | D26: Account disablement and access review on termination or transfer. | E26: =COUNTIF('Config Baseline'!$C:$C,"Personnel Security (PS)") -> 17 | F26: =COUNTIFS('Config Baseline'!$C:$C,"Personnel Security (PS)",'Config Baseline'!$L:$L,"Level 1*") -> 0
A27: PT - PII Processing and Transparency | B27: Authority, purposes, consent and notice for processing personally identifiable information. | C27: Low - privacy governance with limited technical settings. | D27: Data tagging and consent mechanisms. | E27: =COUNTIF('Config Baseline'!$C:$C,"PII Processing and Transparency (PT)") -> 21 | F27: =COUNTIFS('Config Baseline'!$C:$C,"PII Processing and Transparency (PT)",'Config Baseline'!$L:$L,"Level 1*") -> 0
A28: RA - Risk Assessment | B28: Risk assessment, vulnerability scanning and threat hunting. | C28: Medium - scanner and telemetry configuration. | D28: Authenticated vulnerability scanning, scan frequency, hunting telemetry. | E28: =COUNTIF('Config Baseline'!$C:$C,"Risk Assessment (RA)") -> 22 | F28: =COUNTIFS('Config Baseline'!$C:$C,"Risk Assessment (RA)",'Config Baseline'!$L:$L,"Level 1*") -> 3
A29: SA - System and Services Acquisition | B29: Acquisition, system development life cycle, external services and unsupported components. | C29: Medium - secure pipeline, cloud service settings and end-of-life replacement. | D29: CI/CD security testing, cloud service configuration, replacing unsupported OS/firmware. | E29: =COUNTIF('Config Baseline'!$C:$C,"System and Services Acquisition (SA)") -> 109 | F29: =COUNTIFS('Config Baseline'!$C:$C,"System and Services Acquisition (SA)",'Config Baseline'!$L:$L,"Level 1*") -> 0
A30: SC - System and Communications Protection | B30: Boundary protection, cryptography, denial-of-service protection, session authenticity and time synchronization. | C30: Very high - network and cryptographic settings are central. | D30: Firewall/DMZ, segmentation, TLS, DNSSEC, encryption at rest, DDoS, NTP. | E30: =COUNTIF('Config Baseline'!$C:$C,"System and Communications Protection (SC)") -> 138 | F30: =COUNTIFS('Config Baseline'!$C:$C,"System and Communications Protection (SC)",'Config Baseline'!$L:$L,"Level 1*") -> 17
A31: SI - System and Information Integrity | B31: Flaw remediation, malware protection, monitoring, integrity verification and input validation. | C31: Very high - patching, endpoint protection and monitoring settings. | D31: Patching, EDR/anti-malware, IDS/IPS, file integrity monitoring, secure boot, ASLR/DEP. | E31: =COUNTIF('Config Baseline'!$C:$C,"System and Information Integrity (SI)") -> 105 | F31: =COUNTIFS('Config Baseline'!$C:$C,"System and Information Integrity (SI)",'Config Baseline'!$L:$L,"Level 1*") -> 18
A32: SR - Supply Chain Risk Management | B32: Supply chain risk management, provenance and component authenticity. | C32: Low - procurement process with limited technical settings. | D32: Component authenticity checks, secure disposal. | E32: =COUNTIF('Config Baseline'!$C:$C,"Supply Chain Risk Management (SR)") -> 27 | F32: =COUNTIFS('Config Baseline'!$C:$C,"Supply Chain Risk Management (SR)",'Config Baseline'!$L:$L,"Level 1*") -> 0
A34: 3. NIST CSF 2.0 - The Six Functions (Pillars) and Their Relevance to the Configuration Baseline
A35: CSF 2.0 Function | B35: Purpose | C35: Relevance to the configuration baseline | D35: Example configuration items
A36: Govern (GV) | B36: Establishes and monitors the organization's cybersecurity risk management strategy, expectations, policy, roles and supply chain oversight. | C36: Sets the policies and standards from which baseline settings are derived; ensures ownership, exceptions handling and supplier requirements. | D36: Configuration standards and policy, roles for change approval, supplier security requirements.
A37: Identify (ID) | B37: Understands current cybersecurity risks to assets, data and capabilities. | C37: Asset inventory, vulnerability identification and change/exception risk assessment determine what must be baselined. | D37: CMDB/asset inventory, vulnerability scanning, change risk review.
A38: Protect (PR) | B38: Uses safeguards to prevent or reduce cybersecurity risk. | C38: Largest share of baseline settings: identity and access, data protection, platform hardening and infrastructure resilience. | D38: MFA, least privilege, encryption, hardened OS/network/DB settings, segmentation, backup.
A39: Detect (DE) | B39: Finds and analyzes possible cybersecurity attacks and compromises. | C39: Ensures logging, monitoring and alerting are configured so deviations and attacks are visible. | D39: Logging, SIEM rules, IDS/IPS, EDR, integrity monitoring.
A40: Respond (RS) | B40: Takes action regarding a detected cybersecurity incident. | C40: Configuration must allow rapid containment, evidence preservation and reporting. | D40: Isolation actions, forensic logging, incident ticketing and notification settings.
A41: Recover (RC) | B41: Restores assets and operations affected by a cybersecurity incident. | C41: Backups, restore procedures and known-good configurations support fast, trusted recovery. | D41: Backup and restore settings, golden images, DR failover configuration.
A43: 4. Configuration Baseline Levels (3 Levels)
A44: Every control row in the Config Baseline sheet is assigned one of three levels in column L. Level 1 is the strongest and must be present in the configuration; Level 3 has the least impact on the configuration baseline.
...

Sheet Config Baseline
A1: Control ID New | B1: Control ID | C1: Control Family | D1: Control Name | E1: CSF 2.0 Function | F1: CSF 2.0 Category | G1: CSF 2.0 Subcategory ID | H1: CSF 2.0 Subcategory Description | I1: Key Activity | J1: Key Activity (Thai) | K1: IT Domain | L1: Config Baseline Relevance (Level)
A2: ESBIT-AC-01 | B2: AC-01 | C2: Access Control (AC) | D2: Policy and Procedures | E2: Govern (GV) | F2: GV.PO - Policy | G2: GV.PO-01 | H2: Policy for managing cybersecurity risks is established based on organizational context, cybersecurity strategy, and priorities and is communicated and enforced | I2: Not a direct configuration item - define, document, review and communicate the Access Control policy and procedures that drive the technical configuration standards. | J2: ไม่ใช่การ config โดยตรง - กำหนด จัดทำเอกสาร และทบทวนนโยบาย/ขั้นตอนของหมวดการควบคุมการเข้าถึง เพื่อเป็นฐานในการกำหนดมาตรฐาน Config | K2: Governance/Process | L2: Level 3 - Low: governance/process control with no direct technical setting
A3: ESBIT-AC-02 | B3: AC-02 | C3: Access Control (AC) | D3: Account Management | E3: Protect (PR) | F3: PR.AA - Identity Management, Authentication, and Access Control | G3: PR.AA-01 | H3: Identities and credentials for authorized users, services, and hardware are managed by the organization | I3: Configure account types, naming, approval workflow and lifecycle in AD/LDAP, OS, database, network devices and cloud IAM; disable or remove inactive, temporary and shared accounts | J3: กำหนดประเภทบัญชี การอนุมัติ และวงจรชีวิตบัญชีบน AD/OS/DB/อุปกรณ์เครือข่าย/Cloud IAM พร้อมปิดหรือลบบัญชีที่ไม่ใช้งาน ชั่วคราว และบัญชีใช้ร่วม | K3: Identity & Access Management, Cloud, Database | L3: Level 1 - High: mandatory setting that must exist in the configuration baseline
A4: ESBIT-AC-02(01) | B4: AC-02(01) | C4: Access Control (AC) | D4: Account Management | Automated System Account Management | E4: Protect (PR) | F4: PR.AA - Identity Management, Authentication, and Access Control | G4: PR.AA-01 | H4: Identities and credentials for authorized users, services, and hardware are managed by the organization | I4: Enhances AC-02 (Account Management): configure and enforce 'Automated System Account Management' in addition to the base setting, keep it consistent across applicable systems and document approved exceptions. Base scope: Configure account types, naming, approval workflow and lifecycle in AD/LDAP, OS, database, network devices and cloud IAM; disable or remove inactive, temporary and shared accounts | J4: ส่วนขยายของ AC-02: กำหนดค่าและบังคับใช้ 'Automated System Account Management' เพิ่มเติมจากค่าพื้นฐาน ให้สอดคล้องทุกระบบที่เกี่ยวข้อง และบันทึกข้อยกเว้น - กำหนดประเภทบัญชี การอนุมัติ และวงจรชีวิตบัญชีบน AD/OS/DB/อุปกรณ์เครือข่าย/Cloud IAM พร้อมปิดหรือลบบัญชีที่ไม่ใช้งาน ชั่วคราว และบัญชีใช้ร่วม | K4: Identity & Access Management, Cloud, Database | L4: Level 2 - Medium: recommended setting; apply wherever technically applicable
A5: ESBIT-AC-02(02) | B5: AC-02(02) | C5: Access Control (AC) | D5: Account Management | Automated Temporary and Emergency Account Management | E5: Protect (PR) | F5: PR.AA - Identity Management, Authentication, and Access Control | G5: PR.AA-01 | H5: Identities and credentials for authorized users, services, and hardware are managed by the organization | I5: Enhances AC-02 (Account Management): configure and enforce 'Automated Temporary and Emergency Account Management' in addition to the base setting, keep it consistent across applicable systems and document approved exceptions. Base scope: Configure account types, naming, approval workflow and lifecycle in AD/LDAP, OS, database, network devices and cloud IAM; disable or remove inactive, temporary and shared accounts | J5: ส่วนขยายของ AC-02: กำหนดค่าและบังคับใช้ 'Automated Temporary and Emergency Account Management' เพิ่มเติมจากค่าพื้นฐาน ให้สอดคล้องทุกระบบที่เกี่ยวข้อง และบันทึกข้อยกเว้น - กำหนดประเภทบัญชี การอนุมัติ และวงจรชีวิตบัญชีบน AD/OS/DB/อุปกรณ์เครือข่าย/Cloud IAM พร้อมปิดหรือลบบัญชีที่ไม่ใช้งาน ชั่วคราว และบัญชีใช้ร่วม | K5: Identity & Access Management, Cloud, Database | L5: Level 2 - Medium: recommended setting; apply wherever technically applicable
A6: ESBIT-AC-02(03) | B6: AC-02(03) | C6: Access Control (AC) | D6: Account Management | Disable Accounts | E6: Protect (PR) | F6: PR.AA - Identity Management, Authentication, and Access Control | G6: PR.AA-01 | H6: Identities and credentials for authorized users, services, and hardware are managed by the organization | I6: Enhances AC-02 (Account Management): configure and enforce 'Disable Accounts' in addition to the base setting, keep it consistent across applicable systems and document approved exceptions. Base scope: Configure account types, naming, approval workflow and lifecycle in AD/LDAP, OS, database, network devices and cloud IAM; disable or remove inactive, temporary and shared accounts | J6: ส่วนขยายของ AC-02: กำหนดค่าและบังคับใช้ 'Disable Accounts' เพิ่มเติมจากค่าพื้นฐาน ให้สอดคล้องทุกระบบที่เกี่ยวข้อง และบันทึกข้อยกเว้น - กำหนดประเภทบัญชี การอนุมัติ และวงจรชีวิตบัญชีบน AD/OS/DB/อุปกรณ์เครือข่าย/Cloud IAM พร้อมปิดหรือลบบัญชีที่ไม่ใช้งาน ชั่วคราว และบัญชีใช้ร่วม | K6: Identity & Access Management, Cloud, Database | L6: Level 2 - Medium: recommended setting; apply wherever technically applicable
A7: ESBIT-AC-02(04) | B7: AC-02(04) | C7: Access Control (AC) | D7: Account Management | Automated Audit Actions | E7: Protect (PR) | F7: PR.AA - Identity Management, Authentication, and Access Control | G7: PR.AA-01 | H7: Identities and credentials for authorized users, services, and hardware are managed by the organization | I7: Enhances AC-02 (Account Management): configure and enforce 'Automated Audit Actions' in addition to the base setting, keep it consistent across applicable systems and document approved exceptions. Base scope: Configure account types, naming, approval workflow and lifecycle in AD/LDAP, OS, database, network devices and cloud IAM; disable or remove inactive, temporary and shared accounts | J7: ส่วนขยายของ AC-02: กำหนดค่าและบังคับใช้ 'Automated Audit Actions' เพิ่มเติมจากค่าพื้นฐาน ให้สอดคล้องทุกระบบที่เกี่ยวข้อง และบันทึกข้อยกเว้น - กำหนดประเภทบัญชี การอนุมัติ และวงจรชีวิตบัญชีบน AD/OS/DB/อุปกรณ์เครือข่าย/Cloud IAM พร้อมปิดหรือลบบัญชีที่ไม่ใช้งาน ชั่วคราว และบัญชีใช้ร่วม | K7: Identity & Access Management, Cloud, Database | L7: Level 1 - High: mandatory setting that must exist in the configuration baseline
A8: ESBIT-AC-02(05) | B8: AC-02(05) | C8: Access Control (AC) | D8: Account Management | Inactivity Logout | E8: Protect (PR) | F8: PR.AA - Identity Management, Authentication, and Access Control | G8: PR.AA-01 | H8: Identities and credentials for authorized users, services, and hardware are managed by the organization | I8: Enhances AC-02 (Account Management): configure and enforce 'Inactivity Logout' in addition to the base setting, keep it consistent across applicable systems and document approved exceptions. Base scope: Configure account types, naming, approval workflow and lifecycle in AD/LDAP, OS, database, network devices and cloud IAM; disable or remove inactive, temporary and shared accounts | J8: ส่วนขยายของ AC-02: กำหนดค่าและบังคับใช้ 'Inactivity Logout' เพิ่มเติมจากค่าพื้นฐาน ให้สอดคล้องทุกระบบที่เกี่ยวข้อง และบันทึกข้อยกเว้น - กำหนดประเภทบัญชี การอนุมัติ และวงจรชีวิตบัญชีบน AD/OS/DB/อุปกรณ์เครือข่าย/Cloud IAM พร้อมปิดหรือลบบัญชีที่ไม่ใช้งาน ชั่วคราว และบัญชีใช้ร่วม | K8: Identity & Access Management, Cloud, Database | L8: Level 2 - Medium: recommended setting; apply wherever technically applicable
A9: ESBIT-AC-02(06) | B9: AC-02(06) | C9: Access Control (AC) | D9: Account Management | Dynamic Privilege Management | E9: Protect (PR) | F9: PR.AA - Identity Management, Authentication, and Access Control | G9: PR.AA-01 | H9: Identities and credentials for authorized users, services, and hardware are managed by the organization | I9: Enhances AC-02 (Account Management): configure and enforce 'Dynamic Privilege Management' in addition to the base setting, keep it consistent across applicable systems and document approved exceptions. Base scope: Configure account types, naming, approval workflow and lifecycle in AD/LDAP, OS, database, network devices and cloud IAM; disable or remove inactive, temporary and shared accounts | J9: ส่วนขยายของ AC-02: กำหนดค่าและบังคับใช้ 'Dynamic Privilege Management' เพิ่มเติมจากค่าพื้นฐาน ให้สอดคล้องทุกระบบที่เกี่ยวข้อง และบันทึกข้อยกเว้น - กำหนดประเภทบัญชี การอนุมัติ และวงจรชีวิตบัญชีบน AD/OS/DB/อุปกรณ์เครือข่าย/Cloud IAM พร้อมปิดหรือลบบัญชีที่ไม่ใช้งาน ชั่วคราว และบัญชีใช้ร่วม | K9: Identity & Access Management, Cloud, Database | L9: Level 2 - Medium: recommended setting; apply wherever technically applicable
A10: ESBIT-AC-02(07) | B10: AC-02(07) | C10: Access Control (AC) | D10: Account Management | Privileged User Accounts | E10: Protect (PR) | F10: PR.AA - Identity Management, Authentication, and Access Control | G10: PR.AA-01 | H10: Identities and credentials for authorized users, services, and hardware are managed by the organization | I10: Enhances AC-02 (Account Management): configure and enforce 'Privileged User Accounts' in addition to the base setting, keep it consistent across applicable systems and document approved exceptions. Base scope: Configure account types, naming, approval workflow and lifecycle in AD/LDAP, OS, database, network devices and cloud IAM; disable or remove inactive, temporary and shared accounts | J10: ส่วนขยายของ AC-02: กำหนดค่าและบังคับใช้ 'Privileged User Accounts' เพิ่มเติมจากค่าพื้นฐาน ให้สอดคล้องทุกระบบที่เกี่ยวข้อง และบันทึกข้อยกเว้น - กำหนดประเภทบัญชี การอนุมัติ และวงจรชีวิตบัญชีบน AD/OS/DB/อุปกรณ์เครือข่าย/Cloud IAM พร้อมปิดหรือลบบัญชีที่ไม่ใช้งาน ชั่วคราว และบัญชีใช้ร่วม | K10: Identity & Access Management, Cloud, Database | L10: Level 1 - High: mandatory setting that must exist in the configuration baseline
A11: ESBIT-AC-02(08) | B11: AC-02(08) | C11: Access Control (AC) | D11: Account Management | Dynamic Account Management | E11: Protect (PR) | F11: PR.AA - Identity Management, Authentication, and Access Control | G11: PR.AA-01 | H11: Identities and credentials for authorized users, services, and hardware are managed by the organization | I11: Enhances AC-02 (Account Management): configure and enforce 'Dynamic Account Management' in addition to the base setting, keep it consistent across applicable systems and document approved exceptions. Base scope: Configure account types, naming, approval workflow and lifecycle in AD/LDAP, OS, database, network devices and cloud IAM; disable or remove inactive, temporary and shared accounts | J11: ส่วนขยายของ AC-02: กำหนดค่าและบังคับใช้ 'Dynamic Account Management' เพิ่มเติมจากค่าพื้นฐาน ให้สอดคล้องทุกระบบที่เกี่ยวข้อง และบันทึกข้อยกเว้น - กำหนดประเภทบัญชี การอนุมัติ และวงจรชีวิตบัญชีบน AD/OS/DB/อุปกรณ์เครือข่าย/Cloud IAM พร้อมปิดหรือลบบัญชีที่ไม่ใช้งาน ชั่วคราว และบัญชีใช้ร่วม | K11: Identity & Access Management, Cloud, Database | L11: Level 2 - Medium: recommended setting; apply wherever technically applicable
A12: ESBIT-AC-02(09) | B12: AC-02(09) | C12: Access Control (AC) | D12: Account Management | Restrictions on Use of Shared and Group Accounts | E12: Protect (PR) | F12: PR.AA - Identity Management, Authentication, and Access Control | G12: PR.AA-01 | H12: Identities and credentials for authorized users, services, and hardware are managed by the organization | I12: Enhances AC-02 (Account Management): configure and enforce 'Restrictions on Use of Shared and Group Accounts' in addition to the base setting, keep it consistent across applicable systems and document approved exceptions. Base scope: Configure account types, naming, approval workflow and lifecycle in AD/LDAP, OS, database, network devices and cloud IAM; disable or remove inactive, temporary and shared accounts | J12: ส่วนขยายของ AC-02: กำหนดค่าและบังคับใช้ 'Restrictions on Use of Shared and Group Accounts' เพิ่มเติมจากค่าพื้นฐาน ให้สอดคล้องทุกระบบที่เกี่ยวข้อง และบันทึกข้อยกเว้น - กำหนดประเภทบัญชี การอนุมัติ และวงจรชีวิตบัญชีบน AD/OS/DB/อุปกรณ์เครือข่าย/Cloud IAM พร้อมปิดหรือลบบัญชีที่ไม่ใช้งาน ชั่วคราว และบัญชีใช้ร่วม | K12: Identity & Access Management, Cloud, Database | L12: Level 2 - Medium: recommended setting; apply wherever technically applicable
... A1017: ESBIT-SR-12 | B1017: SR-12 | C1017: Supply Chain Risk Management (SR) | D1017: Component Disposal | E1017: Protect (PR) | F1017: PR.PS - Platform Security | G1017: PR.PS-03 | H1017: Hardware is maintained, replaced, and removed commensurate with risk | I1017: Dispose of components using secure sanitization and destruction | J1017: กำจัดคอมโพเนนต์ด้วยการลบข้อมูลและทำลายอย่างปลอดภัย | K1017: Infrastructure (Server/OS), Data Protection/Storage | L1017: Level 3 - Low: optional or limited impact; apply based on risk and context

Sheet Summary
A1: Control Family | B1: Level 1 | C1: Level 2 | D1: Level 3 | E1: Total
A2: Access Control (AC) | B2: =COUNTIFS('Config Baseline'!$C:$C,$A2,'Config Baseline'!$L:$L,"Level 1*") -> 22 | C2: =COUNTIFS('Config Baseline'!$C:$C,$A2,'Config Baseline'!$L:$L,"Level 2*") -> 75 | D2: =COUNTIFS('Config Baseline'!$C:$C,$A2,'Config Baseline'!$L:$L,"Level 3*") -> 30 | E2: =SUM(B2:D2) -> 127
A3: Awareness and Training (AT) | B3: =COUNTIFS('Config Baseline'!$C:$C,$A3,'Config Baseline'!$L:$L,"Level 1*") -> 0 | C3: =COUNTIFS('Config Baseline'!$C:$C,$A3,'Config Baseline'!$L:$L,"Level 2*") -> 0 | D3: =COUNTIFS('Config Baseline'!$C:$C,$A3,'Config Baseline'!$L:$L,"Level 3*") -> 16 | E3: =SUM(B3:D3) -> 16
A4: Audit and Accountability (AU) | B4: =COUNTIFS('Config Baseline'!$C:$C,$A4,'Config Baseline'!$L:$L,"Level 1*") -> 12 | C4: =COUNTIFS('Config Baseline'!$C:$C,$A4,'Config Baseline'!$L:$L,"Level 2*") -> 19 | D4: =COUNTIFS('Config Baseline'!$C:$C,$A4,'Config Baseline'!$L:$L,"Level 3*") -> 26 | E4: =SUM(B4:D4) -> 57
A5: Assessment, Authorization, and Monitoring (CA) | B5: =COUNTIFS('Config Baseline'!$C:$C,$A5,'Config Baseline'!$L:$L,"Level 1*") -> 0 | C5: =COUNTIFS('Config Baseline'!$C:$C,$A5,'Config Baseline'!$L:$L,"Level 2*") -> 3 | D5: =COUNTIFS('Config Baseline'!$C:$C,$A5,'Config Baseline'!$L:$L,"Level 3*") -> 22 | E5: =SUM(B5:D5) -> 25
A6: Configuration Management (CM) | B6: =COUNTIFS('Config Baseline'!$C:$C,$A6,'Config Baseline'!$L:$L,"Level 1*") -> 8 | C6: =COUNTIFS('Config Baseline'!$C:$C,$A6,'Config Baseline'!$L:$L,"Level 2*") -> 37 | D6: =COUNTIFS('Config Baseline'!$C:$C,$A6,'Config Baseline'!$L:$L,"Level 3*") -> 12 | E6: =SUM(B6:D6) -> 57
A7: Contingency Planning (CP) | B7: =COUNTIFS('Config Baseline'!$C:$C,$A7,'Config Baseline'!$L:$L,"Level 1*") -> 3 | C7: =COUNTIFS('Config Baseline'!$C:$C,$A7,'Config Baseline'!$L:$L,"Level 2*") -> 9 | D7: =COUNTIFS('Config Baseline'!$C:$C,$A7,'Config Baseline'!$L:$L,"Level 3*") -> 37 | E7: =SUM(B7:D7) -> 49
A8: Identification and Authentication (IA) | B8: =COUNTIFS('Config Baseline'!$C:$C,$A8,'Config Baseline'!$L:$L,"Level 1*") -> 7 | C8: =COUNTIFS('Config Baseline'!$C:$C,$A8,'Config Baseline'!$L:$L,"Level 2*") -> 36 | D8: =COUNTIFS('Config Baseline'!$C:$C,$A8,'Config Baseline'!$L:$L,"Level 3*") -> 18 | E8: =SUM(B8:D8) -> 61
A9: Incident Response (IR) | B9: =COUNTIFS('Config Baseline'!$C:$C,$A9,'Config Baseline'!$L:$L,"Level 1*") -> 0 | C9: =COUNTIFS('Config Baseline'!$C:$C,$A9,'Config Baseline'!$L:$L,"Level 2*") -> 1 | D9: =COUNTIFS('Config Baseline'!$C:$C,$A9,'Config Baseline'!$L:$L,"Level 3*") -> 38 | E9: =SUM(B9:D9) -> 39
A10: Maintenance (MA) | B10: =COUNTIFS('Config Baseline'!$C:$C,$A10,'Config Baseline'!$L:$L,"Level 1*") -> 3 | C10: =COUNTIFS('Config Baseline'!$C:$C,$A10,'Config Baseline'!$L:$L,"Level 2*") -> 4 | D10: =COUNTIFS('Config Baseline'!$C:$C,$A10,'Config Baseline'!$L:$L,"Level 3*") -> 21 | E10: =SUM(B10:D10) -> 28
A11: Media Protection (MP) | B11: =COUNTIFS('Config Baseline'!$C:$C,$A11,'Config Baseline'!$L:$L,"Level 1*") -> 0 | C11: =COUNTIFS('Config Baseline'!$C:$C,$A11,'Config Baseline'!$L:$L,"Level 2*") -> 6 | D11: =COUNTIFS('Config Baseline'!$C:$C,$A11,'Config Baseline'!$L:$L,"Level 3*") -> 14 | E11: =SUM(B11:D11) -> 20
A12: Physical and Environmental Protection (PE) | B12: =COUNTIFS('Config Baseline'!$C:$C,$A12,'Config Baseline'!$L:$L,"Level 1*") -> 0 | C12: =COUNTIFS('Config Baseline'!$C:$C,$A12,'Config Baseline'!$L:$L,"Level 2*") -> 0 | D12: =COUNTIFS('Config Baseline'!$C:$C,$A12,'Config Baseline'!$L:$L,"Level 3*") -> 50 | E12: =SUM(B12:D12) -> 50
A13: Planning (PL) | B13: =COUNTIFS('Config Baseline'!$C:$C,$A13,'Config Baseline'!$L:$L,"Level 1*") -> 0 | C13: =COUNTIFS('Config Baseline'!$C:$C,$A13,'Config Baseline'!$L:$L,"Level 2*") -> 1 | D13: =COUNTIFS('Config Baseline'!$C:$C,$A13,'Config Baseline'!$L:$L,"Level 3*") -> 10 | E13: =SUM(B13:D13) -> 11
... A21: Supply Chain Risk Management (SR) | B21: =COUNTIFS('Config Baseline'!$C:$C,$A21,'Config Baseline'!$L:$L,"Level 1*") -> 0 | C21: =COUNTIFS('Config Baseline'!$C:$C,$A21,'Config Baseline'!$L:$L,"Level 2*") -> 0 | D21: =COUNTIFS('Config Baseline'!$C:$C,$A21,'Config Baseline'!$L:$L,"Level 3*") -> 27 | E21: =SUM(B21:D21) -> 27
A22: Total | B22: =SUM(B2:B21) -> 93 | C22: =SUM(C2:C21) -> 311 | D22: =SUM(D2:D21) -> 612 | E22: =SUM(E2:E21) -> 1016
A24: IT Domain (a control may touch more than one domain) | B24: Rows | C24: Level 1
A25: Network | B25: =COUNTIF('Config Baseline'!$K:$K,"*"&$A25&"*") -> 301 | C25: =COUNTIFS('Config Baseline'!$K:$K,"*"&$A25&"*",'Config Baseline'!$L:$L,"Level 1*") -> 58
A26: Cloud | B26: =COUNTIF('Config Baseline'!$K:$K,"*"&$A26&"*") -> 216 | C26: =COUNTIFS('Config Baseline'!$K:$K,"*"&$A26&"*",'Config Baseline'!$L:$L,"Level 1*") -> 39
A27: Database | B27: =COUNTIF('Config Baseline'!$K:$K,"*"&$A27&"*") -> 113 | C27: =COUNTIFS('Config Baseline'!$K:$K,"*"&$A27&"*",'Config Baseline'!$L:$L,"Level 1*") -> 25
A28: Infrastructure (Server/OS) | B28: =COUNTIF('Config Baseline'!$K:$K,"*"&$A28&"*") -> 337 | C28: =COUNTIFS('Config Baseline'!$K:$K,"*"&$A28&"*",'Config Baseline'!$L:$L,"Level 1*") -> 57
A29: Identity & Access Management | B29: =COUNTIF('Config Baseline'!$K:$K,"*"&$A29&"*") -> 119 | C29: =COUNTIFS('Config Baseline'!$K:$K,"*"&$A29&"*",'Config Baseline'!$L:$L,"Level 1*") -> 21
A30: Application/Software | B30: =COUNTIF('Config Baseline'!$K:$K,"*"&$A30&"*") -> 235 | C30: =COUNTIFS('Config Baseline'!$K:$K,"*"&$A30&"*",'Config Baseline'!$L:$L,"Level 1*") -> 23
A31: Endpoint/Mobile | B31: =COUNTIF('Config Baseline'!$K:$K,"*"&$A31&"*") -> 45 | C31: =COUNTIFS('Config Baseline'!$K:$K,"*"&$A31&"*",'Config Baseline'!$L:$L,"Level 1*") -> 8
A32: Physical/Facility (Data Center) | B32: =COUNTIF('Config Baseline'!$K:$K,"*"&$A32&"*") -> 53 | C32: =COUNTIFS('Config Baseline'!$K:$K,"*"&$A32&"*",'Config Baseline'!$L:$L,"Level 1*") -> 0
A33: Logging & Monitoring | B33: =COUNTIF('Config Baseline'!$K:$K,"*"&$A33&"*") -> 100 | C33: =COUNTIFS('Config Baseline'!$K:$K,"*"&$A33&"*",'Config Baseline'!$L:$L,"Level 1*") -> 14
A34: Cryptography/PKI | B34: =COUNTIF('Config Baseline'!$K:$K,"*"&$A34&"*") -> 22 | C34: =COUNTIFS('Config Baseline'!$K:$K,"*"&$A34&"*",'Config Baseline'!$L:$L,"Level 1*") -> 6
A35: Data Protection/Storage | B35: =COUNTIF('Config Baseline'!$K:$K,"*"&$A35&"*") -> 62 | C35: =COUNTIFS('Config Baseline'!$K:$K,"*"&$A35&"*",'Config Baseline'!$L:$L,"Level 1*") -> 3
A36: Backup/DR/Resilience | B36: =COUNTIF('Config Baseline'!$K:$K,"*"&$A36&"*") -> 33 | C36: =COUNTIFS('Config Baseline'!$K:$K,"*"&$A36&"*",'Config Baseline'!$L:$L,"Level 1*") -> 3
... A39: Privacy | B39: =COUNTIF('Config Baseline'!$K:$K,"*"&$A39&"*") -> 20 | C39: =COUNTIFS('Config Baseline'!$K:$K,"*"&$A39&"*",'Config Baseline'!$L:$L,"Level 1*") -> 0
