Workbook

Sheet Introduction
A1: Configuration Baseline based on NIST SP 800-53 Rev. 5 (Release 5.2.0) with NIST CSF 2.0 Mapping
A2: Prefix ESBIT- is applied to every original NIST control identifier to form the new Control ID (for example AC-01 becomes ESBIT-AC-01). Sheets: Introduction, Config Baseline (main register), Summary, Domain Summary, Baseline Summary (control families and IDs per topic), and one baseline sheet per topic: Cloud, Network, Identity, Monitoring, Database, Application, Backup, Governance, Physical and Third Party, plus Cloud Coverage Check.
A4: 1. Purpose of the Configuration Baseline
A5: This configuration baseline is established so that every cloud, network, database and infrastructure component is configured in accordance with a documented security baseline, giving the organization a consistent, repeatable and auditable way to harden its systems.
A6: It translates the NIST SP 800-53 Rev. 5 control catalog (20 families, base controls and control enhancements) into concrete configuration expectations, identifies which IT domain each control affects, and rates how strongly each control depends on technical configuration, so that administrators can prioritize what must be present in device and system configurations.
A7: The baseline supports: (1) a common security standard for all environments; (2) detection of configuration drift and unauthorized change; (3) evidence for internal audit and compliance reviews; and (4) alignment of technical settings with NIST CSF 2.0 outcomes.
A8: How to use the Config Baseline sheet: filter column K (IT domain) to select the technology in scope, filter column L to start with Level 1 items, read column I (English) or J (Thai) for the key configuration activity, then map each item to the vendor-specific setting (for example CIS Benchmark or STIG) for your platform.
A9: Important notes: the CSF 2.0 mapping and the Level rating are analyst-derived guidance for building the baseline and should be validated against the official NIST SP 800-53 to CSF 2.0 crosswalk and the organization's risk assessment. Withdrawn controls are excluded. Enhancement levels are derived from the base control (one level lower unless the enhancement concerns encryption, authentication, privilege, integrity, audit or deny-by-default).
A10: IT Domain (column K) uses ten domains: Network, Cloud, Identity, Monitoring, Database, Application, Backup, Governance, Physical and Third Party. A control can belong to more than one domain. The Cloud and Network domains are the scope of the cloud and network configuration baselines; see the Domain Summary sheet for counts and coverage by family.
A12: 2. The 20 NIST SP 800-53 Control Families and Their Relevance to the Configuration Baseline
A13: Control Family | B13: What it covers | C13: Relevance to the configuration baseline | D13: Typical configuration focus | E13: Rows in register | F13: of which Level 1
A14: AC - Access Control | B14: Who and what may access systems, data and networks, and how sessions and information flows are controlled. | C14: High - directly defines account, privilege, session, remote access and network flow settings. | D14: Account lockout, session timeout, least-privilege roles, VPN/remote access, firewall rules, login banner, wireless security. | E14: =COUNTIF('Config Baseline'!$C:$C,"Access Control (AC)") -> 127 | F14: =COUNTIFS('Config Baseline'!$C:$C,"Access Control (AC)",'Config Baseline'!$L:$L,"Level 1*") -> 22
A15: AT - Awareness and Training | B15: Security awareness and role-based training. | C15: Low - people/process control that supports correct configuration by trained administrators. | D15: Administrator and developer training on secure configuration. | E15: =COUNTIF('Config Baseline'!$C:$C,"Awareness and Training (AT)") -> 16 | F15: =COUNTIFS('Config Baseline'!$C:$C,"Awareness and Training (AT)",'Config Baseline'!$L:$L,"Level 1*") -> 0
A16: AU - Audit and Accountability | B16: Event logging, log content, protection, retention, time stamps and review. | C16: High - logging must be enabled and configured on every component. | D16: Enable logging, log format, NTP, central syslog/SIEM forwarding, retention, log integrity. | E16: =COUNTIF('Config Baseline'!$C:$C,"Audit and Accountability (AU)") -> 57 | F16: =COUNTIFS('Config Baseline'!$C:$C,"Audit and Accountability (AU)",'Config Baseline'!$L:$L,"Level 1*") -> 12
A17: CA - Assessment, Authorization, and Monitoring | B17: Control assessment, system interconnection, POA&M, continuous monitoring and penetration testing. | C17: Medium - drives compliance checking and monitoring of configuration. | D17: Configuration compliance scans, interconnection rules, drift monitoring. | E17: =COUNTIF('Config Baseline'!$C:$C,"Assessment, Authorization, and Monitoring (CA)") -> 25 | F17: =COUNTIFS('Config Baseline'!$C:$C,"Assessment, Authorization, and Monitoring (CA)",'Config Baseline'!$L:$L,"Level 1*") -> 0
A18: CM - Configuration Management | B18: Baseline configuration, change control, least functionality, software restrictions and inventory. | C18: Very high - the core of the configuration baseline. | D18: Hardened baselines (CIS/STIG), change control, disable unused services, allowlisting, asset inventory. | E18: =COUNTIF('Config Baseline'!$C:$C,"Configuration Management (CM)") -> 57 | F18: =COUNTIFS('Config Baseline'!$C:$C,"Configuration Management (CM)",'Config Baseline'!$L:$L,"Level 1*") -> 8
A19: CP - Contingency Planning | B19: Contingency planning, backup, alternate sites, telecommunications and recovery. | C19: Medium to high - backup, replication and failover settings. | D19: Backup jobs and encryption, replication, DR failover, redundant links. | E19: =COUNTIF('Config Baseline'!$C:$C,"Contingency Planning (CP)") -> 49 | F19: =COUNTIFS('Config Baseline'!$C:$C,"Contingency Planning (CP)",'Config Baseline'!$L:$L,"Level 1*") -> 3
A20: IA - Identification and Authentication | B20: Authentication of users, devices and services and management of authenticators. | C20: High - authentication settings on every platform. | D20: MFA, password policy, 802.1X/NAC, certificates, service identities, SSO. | E20: =COUNTIF('Config Baseline'!$C:$C,"Identification and Authentication (IA)") -> 61 | F20: =COUNTIFS('Config Baseline'!$C:$C,"Identification and Authentication (IA)",'Config Baseline'!$L:$L,"Level 1*") -> 7
A21: IR - Incident Response | B21: Incident handling capability, training, testing and reporting. | C21: Low to medium - mostly process, with tooling configuration for handling. | D21: SIEM/SOAR playbooks, containment actions, ticketing. | E21: =COUNTIF('Config Baseline'!$C:$C,"Incident Response (IR)") -> 39 | F21: =COUNTIFS('Config Baseline'!$C:$C,"Incident Response (IR)",'Config Baseline'!$L:$L,"Level 1*") -> 0
A22: MA - Maintenance | B22: Controlled and remote maintenance, maintenance tools and personnel. | C22: Low to medium - remote maintenance session settings. | D22: Vendor remote access with MFA, encryption, logging and session termination. | E22: =COUNTIF('Config Baseline'!$C:$C,"Maintenance (MA)") -> 28 | F22: =COUNTIFS('Config Baseline'!$C:$C,"Maintenance (MA)",'Config Baseline'!$L:$L,"Level 1*") -> 3
A23: MP - Media Protection | B23: Access, marking, storage, transport and sanitization of media. | C23: Low to medium - removable media and encryption settings. | D23: USB/removable media control, disk encryption, secure wipe. | E23: =COUNTIF('Config Baseline'!$C:$C,"Media Protection (MP)") -> 20 | F23: =COUNTIFS('Config Baseline'!$C:$C,"Media Protection (MP)",'Config Baseline'!$L:$L,"Level 1*") -> 0
A24: PE - Physical and Environmental Protection | B24: Physical access, monitoring, power, fire and environmental protection. | C24: Low - facility controls rather than IT configuration. | D24: Badge/CCTV systems, UPS, fire suppression, HVAC monitoring. | E24: =COUNTIF('Config Baseline'!$C:$C,"Physical and Environmental Protection (PE)") -> 50 | F24: =COUNTIFS('Config Baseline'!$C:$C,"Physical and Environmental Protection (PE)",'Config Baseline'!$L:$L,"Level 1*") -> 0
A25: PL - Planning | B25: Security planning, rules of behavior, security architecture and baseline selection. | C25: Medium - architecture and baseline tailoring drive the design. | D25: Zoning, defense in depth, segmentation, central management. | E25: =COUNTIF('Config Baseline'!$C:$C,"Planning (PL)") -> 11 | F25: =COUNTIFS('Config Baseline'!$C:$C,"Planning (PL)",'Config Baseline'!$L:$L,"Level 1*") -> 0
A26: PM - Program Management | B26: Enterprise security and privacy program management. | C26: Low - governance with no direct device configuration. | D26: Program plans, roles, metrics and risk strategy. | E26: =COUNTIF('Config Baseline'!$C:$C,"Program Management (PM)") -> 37 | F26: =COUNTIFS('Config Baseline'!$C:$C,"Program Management (PM)",'Config Baseline'!$L:$L,"Level 1*") -> 0
A27: PS - Personnel Security | B27: Personnel screening, termination, transfer and access agreements. | C27: Low - process, with account de-provisioning settings. | D27: Account disablement and access review on termination or transfer. | E27: =COUNTIF('Config Baseline'!$C:$C,"Personnel Security (PS)") -> 17 | F27: =COUNTIFS('Config Baseline'!$C:$C,"Personnel Security (PS)",'Config Baseline'!$L:$L,"Level 1*") -> 0
A28: PT - PII Processing and Transparency | B28: Authority, purposes, consent and notice for processing personally identifiable information. | C28: Low - privacy governance with limited technical settings. | D28: Data tagging and consent mechanisms. | E28: =COUNTIF('Config Baseline'!$C:$C,"PII Processing and Transparency (PT)") -> 21 | F28: =COUNTIFS('Config Baseline'!$C:$C,"PII Processing and Transparency (PT)",'Config Baseline'!$L:$L,"Level 1*") -> 0
A29: RA - Risk Assessment | B29: Risk assessment, vulnerability scanning and threat hunting. | C29: Medium - scanner and telemetry configuration. | D29: Authenticated vulnerability scanning, scan frequency, hunting telemetry. | E29: =COUNTIF('Config Baseline'!$C:$C,"Risk Assessment (RA)") -> 22 | F29: =COUNTIFS('Config Baseline'!$C:$C,"Risk Assessment (RA)",'Config Baseline'!$L:$L,"Level 1*") -> 3
A30: SA - System and Services Acquisition | B30: Acquisition, system development life cycle, external services and unsupported components. | C30: Medium - secure pipeline, cloud service settings and end-of-life replacement. | D30: CI/CD security testing, cloud service configuration, replacing unsupported OS/firmware. | E30: =COUNTIF('Config Baseline'!$C:$C,"System and Services Acquisition (SA)") -> 109 | F30: =COUNTIFS('Config Baseline'!$C:$C,"System and Services Acquisition (SA)",'Config Baseline'!$L:$L,"Level 1*") -> 0
A31: SC - System and Communications Protection | B31: Boundary protection, cryptography, denial-of-service protection, session authenticity and time synchronization. | C31: Very high - network and cryptographic settings are central. | D31: Firewall/DMZ, segmentation, TLS, DNSSEC, encryption at rest, DDoS, NTP. | E31: =COUNTIF('Config Baseline'!$C:$C,"System and Communications Protection (SC)") -> 138 | F31: =COUNTIFS('Config Baseline'!$C:$C,"System and Communications Protection (SC)",'Config Baseline'!$L:$L,"Level 1*") -> 17
A32: SI - System and Information Integrity | B32: Flaw remediation, malware protection, monitoring, integrity verification and input validation. | C32: Very high - patching, endpoint protection and monitoring settings. | D32: Patching, EDR/anti-malware, IDS/IPS, file integrity monitoring, secure boot, ASLR/DEP. | E32: =COUNTIF('Config Baseline'!$C:$C,"System and Information Integrity (SI)") -> 105 | F32: =COUNTIFS('Config Baseline'!$C:$C,"System and Information Integrity (SI)",'Config Baseline'!$L:$L,"Level 1*") -> 18
A33: SR - Supply Chain Risk Management | B33: Supply chain risk management, provenance and component authenticity. | C33: Low - procurement process with limited technical settings. | D33: Component authenticity checks, secure disposal. | E33: =COUNTIF('Config Baseline'!$C:$C,"Supply Chain Risk Management (SR)") -> 27 | F33: =COUNTIFS('Config Baseline'!$C:$C,"Supply Chain Risk Management (SR)",'Config Baseline'!$L:$L,"Level 1*") -> 0
A35: 3. NIST CSF 2.0 - The Six Functions (Pillars) and Their Relevance to the Configuration Baseline
A36: CSF 2.0 Function | B36: Purpose | C36: Relevance to the configuration baseline | D36: Example configuration items
A37: Govern (GV) | B37: Establishes and monitors the organization's cybersecurity risk management strategy, expectations, policy, roles and supply chain oversight. | C37: Sets the policies and standards from which baseline settings are derived; ensures ownership, exceptions handling and supplier requirements. | D37: Configuration standards and policy, roles for change approval, supplier security requirements.
A38: Identify (ID) | B38: Understands current cybersecurity risks to assets, data and capabilities. | C38: Asset inventory, vulnerability identification and change/exception risk assessment determine what must be baselined. | D38: CMDB/asset inventory, vulnerability scanning, change risk review.
A39: Protect (PR) | B39: Uses safeguards to prevent or reduce cybersecurity risk. | C39: Largest share of baseline settings: identity and access, data protection, platform hardening and infrastructure resilience. | D39: MFA, least privilege, encryption, hardened OS/network/DB settings, segmentation, backup.
A40: Detect (DE) | B40: Finds and analyzes possible cybersecurity attacks and compromises. | C40: Ensures logging, monitoring and alerting are configured so deviations and attacks are visible. | D40: Logging, SIEM rules, IDS/IPS, EDR, integrity monitoring.
A41: Respond (RS) | B41: Takes action regarding a detected cybersecurity incident. | C41: Configuration must allow rapid containment, evidence preservation and reporting. | D41: Isolation actions, forensic logging, incident ticketing and notification settings.
A42: Recover (RC) | B42: Restores assets and operations affected by a cybersecurity incident. | C42: Backups, restore procedures and known-good configurations support fast, trusted recovery. | D42: Backup and restore settings, golden images, DR failover configuration.
A44: 4. Configuration Baseline Levels (3 Levels)
...

Sheet Config Baseline
A1: Control ID New | B1: Control ID | C1: Control Family | D1: Control Name | E1: CSF 2.0 Function | F1: CSF 2.0 Category | G1: CSF 2.0 Subcategory ID | H1: CSF 2.0 Subcategory Description | I1: Key Activity | J1: Key Activity (Thai) | K1: IT Domain | L1: Config Baseline Relevance (Level)
A2: ESBIT-AC-01 | B2: AC-01 | C2: Access Control (AC) | D2: Policy and Procedures | E2: Govern (GV) | F2: GV.PO - Policy | G2: GV.PO-01 | H2: Policy for managing cybersecurity risks is established based on organizational context, cybersecurity strategy, and priorities and is communicated and enforced | I2: Not a direct configuration item - define, document, review and communicate the Access Control policy and procedures that drive the technical configuration standards. | J2: ไม่ใช่การ config โดยตรง - กำหนด จัดทำเอกสาร และทบทวนนโยบาย/ขั้นตอนของหมวดการควบคุมการเข้าถึง เพื่อเป็นฐานในการกำหนดมาตรฐาน Config | K2: Governance | L2: Level 3 - Low: governance/process control with no direct technical setting
A3: ESBIT-AC-02 | B3: AC-02 | C3: Access Control (AC) | D3: Account Management | E3: Protect (PR) | F3: PR.AA - Identity Management, Authentication, and Access Control | G3: PR.AA-01 | H3: Identities and credentials for authorized users, services, and hardware are managed by the organization | I3: Configure account types, naming, approval workflow and lifecycle in AD/LDAP, OS, database, network devices and cloud IAM; disable or remove inactive, temporary and shared accounts | J3: กำหนดประเภทบัญชี การอนุมัติ และวงจรชีวิตบัญชีบน AD/OS/DB/อุปกรณ์เครือข่าย/Cloud IAM พร้อมปิดหรือลบบัญชีที่ไม่ใช้งาน ชั่วคราว และบัญชีใช้ร่วม | K3: Network, Cloud, Identity, Database | L3: Level 1 - High: mandatory setting that must exist in the configuration baseline
A4: ESBIT-AC-02(01) | B4: AC-02(01) | C4: Access Control (AC) | D4: Account Management | Automated System Account Management | E4: Protect (PR) | F4: PR.AA - Identity Management, Authentication, and Access Control | G4: PR.AA-01 | H4: Identities and credentials for authorized users, services, and hardware are managed by the organization | I4: Enhances AC-02 (Account Management): configure and enforce 'Automated System Account Management' in addition to the base setting, keep it consistent across applicable systems and document approved exceptions. Base scope: Configure account types, naming, approval workflow and lifecycle in AD/LDAP, OS, database, network devices and cloud IAM; disable or remove inactive, temporary and shared accounts | J4: ส่วนขยายของ AC-02: กำหนดค่าและบังคับใช้ 'Automated System Account Management' เพิ่มเติมจากค่าพื้นฐาน ให้สอดคล้องทุกระบบที่เกี่ยวข้อง และบันทึกข้อยกเว้น - กำหนดประเภทบัญชี การอนุมัติ และวงจรชีวิตบัญชีบน AD/OS/DB/อุปกรณ์เครือข่าย/Cloud IAM พร้อมปิดหรือลบบัญชีที่ไม่ใช้งาน ชั่วคราว และบัญชีใช้ร่วม | K4: Network, Cloud, Identity, Database | L4: Level 2 - Medium: recommended setting; apply wherever technically applicable
A5: ESBIT-AC-02(02) | B5: AC-02(02) | C5: Access Control (AC) | D5: Account Management | Automated Temporary and Emergency Account Management | E5: Protect (PR) | F5: PR.AA - Identity Management, Authentication, and Access Control | G5: PR.AA-01 | H5: Identities and credentials for authorized users, services, and hardware are managed by the organization | I5: Enhances AC-02 (Account Management): configure and enforce 'Automated Temporary and Emergency Account Management' in addition to the base setting, keep it consistent across applicable systems and document approved exceptions. Base scope: Configure account types, naming, approval workflow and lifecycle in AD/LDAP, OS, database, network devices and cloud IAM; disable or remove inactive, temporary and shared accounts | J5: ส่วนขยายของ AC-02: กำหนดค่าและบังคับใช้ 'Automated Temporary and Emergency Account Management' เพิ่มเติมจากค่าพื้นฐาน ให้สอดคล้องทุกระบบที่เกี่ยวข้อง และบันทึกข้อยกเว้น - กำหนดประเภทบัญชี การอนุมัติ และวงจรชีวิตบัญชีบน AD/OS/DB/อุปกรณ์เครือข่าย/Cloud IAM พร้อมปิดหรือลบบัญชีที่ไม่ใช้งาน ชั่วคราว และบัญชีใช้ร่วม | K5: Network, Cloud, Identity, Database | L5: Level 2 - Medium: recommended setting; apply wherever technically applicable
A6: ESBIT-AC-02(03) | B6: AC-02(03) | C6: Access Control (AC) | D6: Account Management | Disable Accounts | E6: Protect (PR) | F6: PR.AA - Identity Management, Authentication, and Access Control | G6: PR.AA-01 | H6: Identities and credentials for authorized users, services, and hardware are managed by the organization | I6: Enhances AC-02 (Account Management): configure and enforce 'Disable Accounts' in addition to the base setting, keep it consistent across applicable systems and document approved exceptions. Base scope: Configure account types, naming, approval workflow and lifecycle in AD/LDAP, OS, database, network devices and cloud IAM; disable or remove inactive, temporary and shared accounts | J6: ส่วนขยายของ AC-02: กำหนดค่าและบังคับใช้ 'Disable Accounts' เพิ่มเติมจากค่าพื้นฐาน ให้สอดคล้องทุกระบบที่เกี่ยวข้อง และบันทึกข้อยกเว้น - กำหนดประเภทบัญชี การอนุมัติ และวงจรชีวิตบัญชีบน AD/OS/DB/อุปกรณ์เครือข่าย/Cloud IAM พร้อมปิดหรือลบบัญชีที่ไม่ใช้งาน ชั่วคราว และบัญชีใช้ร่วม | K6: Network, Cloud, Identity, Database | L6: Level 2 - Medium: recommended setting; apply wherever technically applicable
A7: ESBIT-AC-02(04) | B7: AC-02(04) | C7: Access Control (AC) | D7: Account Management | Automated Audit Actions | E7: Protect (PR) | F7: PR.AA - Identity Management, Authentication, and Access Control | G7: PR.AA-01 | H7: Identities and credentials for authorized users, services, and hardware are managed by the organization | I7: Enhances AC-02 (Account Management): configure and enforce 'Automated Audit Actions' in addition to the base setting, keep it consistent across applicable systems and document approved exceptions. Base scope: Configure account types, naming, approval workflow and lifecycle in AD/LDAP, OS, database, network devices and cloud IAM; disable or remove inactive, temporary and shared accounts | J7: ส่วนขยายของ AC-02: กำหนดค่าและบังคับใช้ 'Automated Audit Actions' เพิ่มเติมจากค่าพื้นฐาน ให้สอดคล้องทุกระบบที่เกี่ยวข้อง และบันทึกข้อยกเว้น - กำหนดประเภทบัญชี การอนุมัติ และวงจรชีวิตบัญชีบน AD/OS/DB/อุปกรณ์เครือข่าย/Cloud IAM พร้อมปิดหรือลบบัญชีที่ไม่ใช้งาน ชั่วคราว และบัญชีใช้ร่วม | K7: Network, Cloud, Identity, Database | L7: Level 1 - High: mandatory setting that must exist in the configuration baseline
A8: ESBIT-AC-02(05) | B8: AC-02(05) | C8: Access Control (AC) | D8: Account Management | Inactivity Logout | E8: Protect (PR) | F8: PR.AA - Identity Management, Authentication, and Access Control | G8: PR.AA-01 | H8: Identities and credentials for authorized users, services, and hardware are managed by the organization | I8: Enhances AC-02 (Account Management): configure and enforce 'Inactivity Logout' in addition to the base setting, keep it consistent across applicable systems and document approved exceptions. Base scope: Configure account types, naming, approval workflow and lifecycle in AD/LDAP, OS, database, network devices and cloud IAM; disable or remove inactive, temporary and shared accounts | J8: ส่วนขยายของ AC-02: กำหนดค่าและบังคับใช้ 'Inactivity Logout' เพิ่มเติมจากค่าพื้นฐาน ให้สอดคล้องทุกระบบที่เกี่ยวข้อง และบันทึกข้อยกเว้น - กำหนดประเภทบัญชี การอนุมัติ และวงจรชีวิตบัญชีบน AD/OS/DB/อุปกรณ์เครือข่าย/Cloud IAM พร้อมปิดหรือลบบัญชีที่ไม่ใช้งาน ชั่วคราว และบัญชีใช้ร่วม | K8: Network, Cloud, Identity, Database | L8: Level 2 - Medium: recommended setting; apply wherever technically applicable
A9: ESBIT-AC-02(06) | B9: AC-02(06) | C9: Access Control (AC) | D9: Account Management | Dynamic Privilege Management | E9: Protect (PR) | F9: PR.AA - Identity Management, Authentication, and Access Control | G9: PR.AA-01 | H9: Identities and credentials for authorized users, services, and hardware are managed by the organization | I9: Enhances AC-02 (Account Management): configure and enforce 'Dynamic Privilege Management' in addition to the base setting, keep it consistent across applicable systems and document approved exceptions. Base scope: Configure account types, naming, approval workflow and lifecycle in AD/LDAP, OS, database, network devices and cloud IAM; disable or remove inactive, temporary and shared accounts | J9: ส่วนขยายของ AC-02: กำหนดค่าและบังคับใช้ 'Dynamic Privilege Management' เพิ่มเติมจากค่าพื้นฐาน ให้สอดคล้องทุกระบบที่เกี่ยวข้อง และบันทึกข้อยกเว้น - กำหนดประเภทบัญชี การอนุมัติ และวงจรชีวิตบัญชีบน AD/OS/DB/อุปกรณ์เครือข่าย/Cloud IAM พร้อมปิดหรือลบบัญชีที่ไม่ใช้งาน ชั่วคราว และบัญชีใช้ร่วม | K9: Network, Cloud, Identity, Database | L9: Level 2 - Medium: recommended setting; apply wherever technically applicable
A10: ESBIT-AC-02(07) | B10: AC-02(07) | C10: Access Control (AC) | D10: Account Management | Privileged User Accounts | E10: Protect (PR) | F10: PR.AA - Identity Management, Authentication, and Access Control | G10: PR.AA-01 | H10: Identities and credentials for authorized users, services, and hardware are managed by the organization | I10: Enhances AC-02 (Account Management): configure and enforce 'Privileged User Accounts' in addition to the base setting, keep it consistent across applicable systems and document approved exceptions. Base scope: Configure account types, naming, approval workflow and lifecycle in AD/LDAP, OS, database, network devices and cloud IAM; disable or remove inactive, temporary and shared accounts | J10: ส่วนขยายของ AC-02: กำหนดค่าและบังคับใช้ 'Privileged User Accounts' เพิ่มเติมจากค่าพื้นฐาน ให้สอดคล้องทุกระบบที่เกี่ยวข้อง และบันทึกข้อยกเว้น - กำหนดประเภทบัญชี การอนุมัติ และวงจรชีวิตบัญชีบน AD/OS/DB/อุปกรณ์เครือข่าย/Cloud IAM พร้อมปิดหรือลบบัญชีที่ไม่ใช้งาน ชั่วคราว และบัญชีใช้ร่วม | K10: Network, Cloud, Identity, Database | L10: Level 1 - High: mandatory setting that must exist in the configuration baseline
A11: ESBIT-AC-02(08) | B11: AC-02(08) | C11: Access Control (AC) | D11: Account Management | Dynamic Account Management | E11: Protect (PR) | F11: PR.AA - Identity Management, Authentication, and Access Control | G11: PR.AA-01 | H11: Identities and credentials for authorized users, services, and hardware are managed by the organization | I11: Enhances AC-02 (Account Management): configure and enforce 'Dynamic Account Management' in addition to the base setting, keep it consistent across applicable systems and document approved exceptions. Base scope: Configure account types, naming, approval workflow and lifecycle in AD/LDAP, OS, database, network devices and cloud IAM; disable or remove inactive, temporary and shared accounts | J11: ส่วนขยายของ AC-02: กำหนดค่าและบังคับใช้ 'Dynamic Account Management' เพิ่มเติมจากค่าพื้นฐาน ให้สอดคล้องทุกระบบที่เกี่ยวข้อง และบันทึกข้อยกเว้น - กำหนดประเภทบัญชี การอนุมัติ และวงจรชีวิตบัญชีบน AD/OS/DB/อุปกรณ์เครือข่าย/Cloud IAM พร้อมปิดหรือลบบัญชีที่ไม่ใช้งาน ชั่วคราว และบัญชีใช้ร่วม | K11: Network, Cloud, Identity, Database | L11: Level 2 - Medium: recommended setting; apply wherever technically applicable
A12: ESBIT-AC-02(09) | B12: AC-02(09) | C12: Access Control (AC) | D12: Account Management | Restrictions on Use of Shared and Group Accounts | E12: Protect (PR) | F12: PR.AA - Identity Management, Authentication, and Access Control | G12: PR.AA-01 | H12: Identities and credentials for authorized users, services, and hardware are managed by the organization | I12: Enhances AC-02 (Account Management): configure and enforce 'Restrictions on Use of Shared and Group Accounts' in addition to the base setting, keep it consistent across applicable systems and document approved exceptions. Base scope: Configure account types, naming, approval workflow and lifecycle in AD/LDAP, OS, database, network devices and cloud IAM; disable or remove inactive, temporary and shared accounts | J12: ส่วนขยายของ AC-02: กำหนดค่าและบังคับใช้ 'Restrictions on Use of Shared and Group Accounts' เพิ่มเติมจากค่าพื้นฐาน ให้สอดคล้องทุกระบบที่เกี่ยวข้อง และบันทึกข้อยกเว้น - กำหนดประเภทบัญชี การอนุมัติ และวงจรชีวิตบัญชีบน AD/OS/DB/อุปกรณ์เครือข่าย/Cloud IAM พร้อมปิดหรือลบบัญชีที่ไม่ใช้งาน ชั่วคราว และบัญชีใช้ร่วม | K12: Network, Cloud, Identity, Database | L12: Level 2 - Medium: recommended setting; apply wherever technically applicable
... A1017: ESBIT-SR-12 | B1017: SR-12 | C1017: Supply Chain Risk Management (SR) | D1017: Component Disposal | E1017: Protect (PR) | F1017: PR.PS - Platform Security | G1017: PR.PS-03 | H1017: Hardware is maintained, replaced, and removed commensurate with risk | I1017: Dispose of components using secure sanitization and destruction | J1017: กำจัดคอมโพเนนต์ด้วยการลบข้อมูลและทำลายอย่างปลอดภัย | K1017: Physical | L1017: Level 3 - Low: optional or limited impact; apply based on risk and context

Sheet Summary
A1: Control Family | B1: Level 1 | C1: Level 2 | D1: Level 3 | E1: Total
A2: Access Control (AC) | B2: =COUNTIFS('Config Baseline'!$C:$C,$A2,'Config Baseline'!$L:$L,"Level 1*") -> 22 | C2: =COUNTIFS('Config Baseline'!$C:$C,$A2,'Config Baseline'!$L:$L,"Level 2*") -> 75 | D2: =COUNTIFS('Config Baseline'!$C:$C,$A2,'Config Baseline'!$L:$L,"Level 3*") -> 30 | E2: =SUM(B2:D2) -> 127
A3: Awareness and Training (AT) | B3: =COUNTIFS('Config Baseline'!$C:$C,$A3,'Config Baseline'!$L:$L,"Level 1*") -> 0 | C3: =COUNTIFS('Config Baseline'!$C:$C,$A3,'Config Baseline'!$L:$L,"Level 2*") -> 0 | D3: =COUNTIFS('Config Baseline'!$C:$C,$A3,'Config Baseline'!$L:$L,"Level 3*") -> 16 | E3: =SUM(B3:D3) -> 16
A4: Audit and Accountability (AU) | B4: =COUNTIFS('Config Baseline'!$C:$C,$A4,'Config Baseline'!$L:$L,"Level 1*") -> 12 | C4: =COUNTIFS('Config Baseline'!$C:$C,$A4,'Config Baseline'!$L:$L,"Level 2*") -> 19 | D4: =COUNTIFS('Config Baseline'!$C:$C,$A4,'Config Baseline'!$L:$L,"Level 3*") -> 26 | E4: =SUM(B4:D4) -> 57
A5: Assessment, Authorization, and Monitoring (CA) | B5: =COUNTIFS('Config Baseline'!$C:$C,$A5,'Config Baseline'!$L:$L,"Level 1*") -> 0 | C5: =COUNTIFS('Config Baseline'!$C:$C,$A5,'Config Baseline'!$L:$L,"Level 2*") -> 3 | D5: =COUNTIFS('Config Baseline'!$C:$C,$A5,'Config Baseline'!$L:$L,"Level 3*") -> 22 | E5: =SUM(B5:D5) -> 25
A6: Configuration Management (CM) | B6: =COUNTIFS('Config Baseline'!$C:$C,$A6,'Config Baseline'!$L:$L,"Level 1*") -> 8 | C6: =COUNTIFS('Config Baseline'!$C:$C,$A6,'Config Baseline'!$L:$L,"Level 2*") -> 37 | D6: =COUNTIFS('Config Baseline'!$C:$C,$A6,'Config Baseline'!$L:$L,"Level 3*") -> 12 | E6: =SUM(B6:D6) -> 57
A7: Contingency Planning (CP) | B7: =COUNTIFS('Config Baseline'!$C:$C,$A7,'Config Baseline'!$L:$L,"Level 1*") -> 3 | C7: =COUNTIFS('Config Baseline'!$C:$C,$A7,'Config Baseline'!$L:$L,"Level 2*") -> 9 | D7: =COUNTIFS('Config Baseline'!$C:$C,$A7,'Config Baseline'!$L:$L,"Level 3*") -> 37 | E7: =SUM(B7:D7) -> 49
A8: Identification and Authentication (IA) | B8: =COUNTIFS('Config Baseline'!$C:$C,$A8,'Config Baseline'!$L:$L,"Level 1*") -> 7 | C8: =COUNTIFS('Config Baseline'!$C:$C,$A8,'Config Baseline'!$L:$L,"Level 2*") -> 36 | D8: =COUNTIFS('Config Baseline'!$C:$C,$A8,'Config Baseline'!$L:$L,"Level 3*") -> 18 | E8: =SUM(B8:D8) -> 61
A9: Incident Response (IR) | B9: =COUNTIFS('Config Baseline'!$C:$C,$A9,'Config Baseline'!$L:$L,"Level 1*") -> 0 | C9: =COUNTIFS('Config Baseline'!$C:$C,$A9,'Config Baseline'!$L:$L,"Level 2*") -> 1 | D9: =COUNTIFS('Config Baseline'!$C:$C,$A9,'Config Baseline'!$L:$L,"Level 3*") -> 38 | E9: =SUM(B9:D9) -> 39
A10: Maintenance (MA) | B10: =COUNTIFS('Config Baseline'!$C:$C,$A10,'Config Baseline'!$L:$L,"Level 1*") -> 3 | C10: =COUNTIFS('Config Baseline'!$C:$C,$A10,'Config Baseline'!$L:$L,"Level 2*") -> 4 | D10: =COUNTIFS('Config Baseline'!$C:$C,$A10,'Config Baseline'!$L:$L,"Level 3*") -> 21 | E10: =SUM(B10:D10) -> 28
A11: Media Protection (MP) | B11: =COUNTIFS('Config Baseline'!$C:$C,$A11,'Config Baseline'!$L:$L,"Level 1*") -> 0 | C11: =COUNTIFS('Config Baseline'!$C:$C,$A11,'Config Baseline'!$L:$L,"Level 2*") -> 6 | D11: =COUNTIFS('Config Baseline'!$C:$C,$A11,'Config Baseline'!$L:$L,"Level 3*") -> 14 | E11: =SUM(B11:D11) -> 20
A12: Physical and Environmental Protection (PE) | B12: =COUNTIFS('Config Baseline'!$C:$C,$A12,'Config Baseline'!$L:$L,"Level 1*") -> 0 | C12: =COUNTIFS('Config Baseline'!$C:$C,$A12,'Config Baseline'!$L:$L,"Level 2*") -> 0 | D12: =COUNTIFS('Config Baseline'!$C:$C,$A12,'Config Baseline'!$L:$L,"Level 3*") -> 50 | E12: =SUM(B12:D12) -> 50
A13: Planning (PL) | B13: =COUNTIFS('Config Baseline'!$C:$C,$A13,'Config Baseline'!$L:$L,"Level 1*") -> 0 | C13: =COUNTIFS('Config Baseline'!$C:$C,$A13,'Config Baseline'!$L:$L,"Level 2*") -> 1 | D13: =COUNTIFS('Config Baseline'!$C:$C,$A13,'Config Baseline'!$L:$L,"Level 3*") -> 10 | E13: =SUM(B13:D13) -> 11
... A21: Supply Chain Risk Management (SR) | B21: =COUNTIFS('Config Baseline'!$C:$C,$A21,'Config Baseline'!$L:$L,"Level 1*") -> 0 | C21: =COUNTIFS('Config Baseline'!$C:$C,$A21,'Config Baseline'!$L:$L,"Level 2*") -> 0 | D21: =COUNTIFS('Config Baseline'!$C:$C,$A21,'Config Baseline'!$L:$L,"Level 3*") -> 27 | E21: =SUM(B21:D21) -> 27
A22: Total | B22: =SUM(B2:B21) -> 93 | C22: =SUM(C2:C21) -> 311 | D22: =SUM(D2:D21) -> 612 | E22: =SUM(E2:E21) -> 1016

Sheet Domain Summary
A1: IT Domain Summary - counts of control families, base controls and control IDs (a control can appear in more than one domain)
A3: IT Domain | B3: Families | C3: Base Controls | D3: Control IDs (base + enhancements) | E3: Level 1 | F3: Level 2 | G3: Level 3
A4: Network | B4: =COUNTIF(B32:U32,">0") -> 14 | C4: =SUMPRODUCT(ISNUMBER(SEARCH($A4,'Config Baseline'!$K$2:$K$1017))*ISERROR(SEARCH("(",'Config Baseline'!$B$2:$B$1017))) -> 76 | D4: =COUNTIF('Config Baseline'!$K$2:$K$1017,"*"&$A4&"*") -> 413 | E4: =COUNTIFS('Config Baseline'!$K$2:$K$1017,"*"&$A4&"*",'Config Baseline'!$L$2:$L$1017,"Level 1*") -> 80 | F4: =COUNTIFS('Config Baseline'!$K$2:$K$1017,"*"&$A4&"*",'Config Baseline'!$L$2:$L$1017,"Level 2*") -> 251 | G4: =COUNTIFS('Config Baseline'!$K$2:$K$1017,"*"&$A4&"*",'Config Baseline'!$L$2:$L$1017,"Level 3*") -> 82
A5: Cloud | B5: =COUNTIF(B33:U33,">0") -> 15 | C5: =SUMPRODUCT(ISNUMBER(SEARCH($A5,'Config Baseline'!$K$2:$K$1017))*ISERROR(SEARCH("(",'Config Baseline'!$B$2:$B$1017))) -> 115 | D5: =COUNTIF('Config Baseline'!$K$2:$K$1017,"*"&$A5&"*") -> 596 | E5: =COUNTIFS('Config Baseline'!$K$2:$K$1017,"*"&$A5&"*",'Config Baseline'!$L$2:$L$1017,"Level 1*") -> 87 | F5: =COUNTIFS('Config Baseline'!$K$2:$K$1017,"*"&$A5&"*",'Config Baseline'!$L$2:$L$1017,"Level 2*") -> 285 | G5: =COUNTIFS('Config Baseline'!$K$2:$K$1017,"*"&$A5&"*",'Config Baseline'!$L$2:$L$1017,"Level 3*") -> 224
A6: Identity | B6: =COUNTIF(B34:U34,">0") -> 3 | C6: =SUMPRODUCT(ISNUMBER(SEARCH($A6,'Config Baseline'!$K$2:$K$1017))*ISERROR(SEARCH("(",'Config Baseline'!$B$2:$B$1017))) -> 21 | D6: =COUNTIF('Config Baseline'!$K$2:$K$1017,"*"&$A6&"*") -> 119 | E6: =COUNTIFS('Config Baseline'!$K$2:$K$1017,"*"&$A6&"*",'Config Baseline'!$L$2:$L$1017,"Level 1*") -> 21 | F6: =COUNTIFS('Config Baseline'!$K$2:$K$1017,"*"&$A6&"*",'Config Baseline'!$L$2:$L$1017,"Level 2*") -> 71 | G6: =COUNTIFS('Config Baseline'!$K$2:$K$1017,"*"&$A6&"*",'Config Baseline'!$L$2:$L$1017,"Level 3*") -> 27
A7: Monitoring | B7: =COUNTIF(B35:U35,">0") -> 6 | C7: =SUMPRODUCT(ISNUMBER(SEARCH($A7,'Config Baseline'!$K$2:$K$1017))*ISERROR(SEARCH("(",'Config Baseline'!$B$2:$B$1017))) -> 18 | D7: =COUNTIF('Config Baseline'!$K$2:$K$1017,"*"&$A7&"*") -> 100 | E7: =COUNTIFS('Config Baseline'!$K$2:$K$1017,"*"&$A7&"*",'Config Baseline'!$L$2:$L$1017,"Level 1*") -> 14 | F7: =COUNTIFS('Config Baseline'!$K$2:$K$1017,"*"&$A7&"*",'Config Baseline'!$L$2:$L$1017,"Level 2*") -> 43 | G7: =COUNTIFS('Config Baseline'!$K$2:$K$1017,"*"&$A7&"*",'Config Baseline'!$L$2:$L$1017,"Level 3*") -> 43
A8: Database | B8: =COUNTIF(B36:U36,">0") -> 7 | C8: =SUMPRODUCT(ISNUMBER(SEARCH($A8,'Config Baseline'!$K$2:$K$1017))*ISERROR(SEARCH("(",'Config Baseline'!$B$2:$B$1017))) -> 19 | D8: =COUNTIF('Config Baseline'!$K$2:$K$1017,"*"&$A8&"*") -> 115 | E8: =COUNTIFS('Config Baseline'!$K$2:$K$1017,"*"&$A8&"*",'Config Baseline'!$L$2:$L$1017,"Level 1*") -> 25 | F8: =COUNTIFS('Config Baseline'!$K$2:$K$1017,"*"&$A8&"*",'Config Baseline'!$L$2:$L$1017,"Level 2*") -> 70 | G8: =COUNTIFS('Config Baseline'!$K$2:$K$1017,"*"&$A8&"*",'Config Baseline'!$L$2:$L$1017,"Level 3*") -> 20
A9: Application | B9: =COUNTIF(B37:U37,">0") -> 12 | C9: =SUMPRODUCT(ISNUMBER(SEARCH($A9,'Config Baseline'!$K$2:$K$1017))*ISERROR(SEARCH("(",'Config Baseline'!$B$2:$B$1017))) -> 113 | D9: =COUNTIF('Config Baseline'!$K$2:$K$1017,"*"&$A9&"*") -> 484 | E9: =COUNTIFS('Config Baseline'!$K$2:$K$1017,"*"&$A9&"*",'Config Baseline'!$L$2:$L$1017,"Level 1*") -> 63 | F9: =COUNTIFS('Config Baseline'!$K$2:$K$1017,"*"&$A9&"*",'Config Baseline'!$L$2:$L$1017,"Level 2*") -> 193 | G9: =COUNTIFS('Config Baseline'!$K$2:$K$1017,"*"&$A9&"*",'Config Baseline'!$L$2:$L$1017,"Level 3*") -> 228
A10: Backup | B10: =COUNTIF(B38:U38,">0") -> 1 | C10: =SUMPRODUCT(ISNUMBER(SEARCH($A10,'Config Baseline'!$K$2:$K$1017))*ISERROR(SEARCH("(",'Config Baseline'!$B$2:$B$1017))) -> 6 | D10: =COUNTIF('Config Baseline'!$K$2:$K$1017,"*"&$A10&"*") -> 33 | E10: =COUNTIFS('Config Baseline'!$K$2:$K$1017,"*"&$A10&"*",'Config Baseline'!$L$2:$L$1017,"Level 1*") -> 3 | F10: =COUNTIFS('Config Baseline'!$K$2:$K$1017,"*"&$A10&"*",'Config Baseline'!$L$2:$L$1017,"Level 2*") -> 7 | G10: =COUNTIFS('Config Baseline'!$K$2:$K$1017,"*"&$A10&"*",'Config Baseline'!$L$2:$L$1017,"Level 3*") -> 23
A11: Governance | B11: =COUNTIF(B39:U39,">0") -> 19 | C11: =SUMPRODUCT(ISNUMBER(SEARCH($A11,'Config Baseline'!$K$2:$K$1017))*ISERROR(SEARCH("(",'Config Baseline'!$B$2:$B$1017))) -> 91 | D11: =COUNTIF('Config Baseline'!$K$2:$K$1017,"*"&$A11&"*") -> 179 | E11: =COUNTIFS('Config Baseline'!$K$2:$K$1017,"*"&$A11&"*",'Config Baseline'!$L$2:$L$1017,"Level 1*") -> 0 | F11: =COUNTIFS('Config Baseline'!$K$2:$K$1017,"*"&$A11&"*",'Config Baseline'!$L$2:$L$1017,"Level 2*") -> 6 | G11: =COUNTIFS('Config Baseline'!$K$2:$K$1017,"*"&$A11&"*",'Config Baseline'!$L$2:$L$1017,"Level 3*") -> 173
A12: Physical | B12: =COUNTIF(B40:U40,">0") -> 4 | C12: =SUMPRODUCT(ISNUMBER(SEARCH($A12,'Config Baseline'!$K$2:$K$1017))*ISERROR(SEARCH("(",'Config Baseline'!$B$2:$B$1017))) -> 38 | D12: =COUNTIF('Config Baseline'!$K$2:$K$1017,"*"&$A12&"*") -> 103 | E12: =COUNTIFS('Config Baseline'!$K$2:$K$1017,"*"&$A12&"*",'Config Baseline'!$L$2:$L$1017,"Level 1*") -> 3 | F12: =COUNTIFS('Config Baseline'!$K$2:$K$1017,"*"&$A12&"*",'Config Baseline'!$L$2:$L$1017,"Level 2*") -> 10 | G12: =COUNTIFS('Config Baseline'!$K$2:$K$1017,"*"&$A12&"*",'Config Baseline'!$L$2:$L$1017,"Level 3*") -> 90
A13: Third Party | B13: =COUNTIF(B41:U41,">0") -> 2 | C13: =SUMPRODUCT(ISNUMBER(SEARCH($A13,'Config Baseline'!$K$2:$K$1017))*ISERROR(SEARCH("(",'Config Baseline'!$B$2:$B$1017))) -> 10 | D13: =COUNTIF('Config Baseline'!$K$2:$K$1017,"*"&$A13&"*") -> 32 | E13: =COUNTIFS('Config Baseline'!$K$2:$K$1017,"*"&$A13&"*",'Config Baseline'!$L$2:$L$1017,"Level 1*") -> 0 | F13: =COUNTIFS('Config Baseline'!$K$2:$K$1017,"*"&$A13&"*",'Config Baseline'!$L$2:$L$1017,"Level 2*") -> 3 | G13: =COUNTIFS('Config Baseline'!$K$2:$K$1017,"*"&$A13&"*",'Config Baseline'!$L$2:$L$1017,"Level 3*") -> 29
A14: Unique rows in register (all domains) | C14: =SUMPRODUCT(ISERROR(SEARCH("(",'Config Baseline'!$B$2:$B$1017))*1) -> 300 | D14: =COUNTA('Config Baseline'!$B$2:$B$1017) -> 1016
A15: Note: domain rows overlap, so they add up to more than the unique total.
A17: IT Domain | B17: Scope and assignment note
A18: Network | B18: Routers, switches, firewalls, wireless and DNS/NTP. Baseline scope: AC, AU, CA, CM, CP (links), IA, IR, MA (remote), PL, RA, SA (unsupported devices), SC, SI, SR (authentic components).
A19: Cloud | B19: IaaS/PaaS/SaaS tenant and workload configuration. Baseline scope: AC, AU, CA, CM, CP, IA, IR, RA, SA, SC, SI, SR, plus MP-6, PL-8/9, PS-4/5.
A20: Identity | B20: Account, authentication and privilege management (IAM, directory, SSO/MFA).
A21: Monitoring | B21: Logging, SIEM, monitoring and detection tooling.
A22: Database | B22: Database engines, data stores and data-level protection.
A23: Application | B23: Applications and the operating-system/endpoint software layer (former Infrastructure and Endpoint items were placed here).
A24: Backup | B24: Backup, DR, alternate sites and resilience.
A25: Governance | B25: Policies, procedures, training, risk and privacy governance (non-technical controls).
A26: Physical | B26: Facilities, data center, media, hardware maintenance and hardware supply chain.
A27: Third Party | B27: Suppliers, outsourced services and supply chain risk.
A30: Control IDs (base + enhancements) by domain and family
A31: IT Domain | B31: AC | C31: AT | D31: AU | E31: CA | F31: CM | G31: CP | H31: IA | I31: IR | J31: MA | K31: MP | L31: PE | M31: PL | N31: PM | O31: PS | P31: PT | Q31: RA | R31: SA | S31: SC | T31: SI | U31: SR | V31: Total
A32: Network | B32: =COUNTIFS('Config Baseline'!$C$2:$C$1017,"*("&B$31&")",'Config Baseline'!$K$2:$K$1017,"*"&$A32&"*") -> 97 | C32: =COUNTIFS('Config Baseline'!$C$2:$C$1017,"*("&C$31&")",'Config Baseline'!$K$2:$K$1017,"*"&$A32&"*") -> 0 | D32: =COUNTIFS('Config Baseline'!$C$2:$C$1017,"*("&D$31&")",'Config Baseline'!$K$2:$K$1017,"*"&$A32&"*") -> 38 | E32: =COUNTIFS('Config Baseline'!$C$2:$C$1017,"*("&E$31&")",'Config Baseline'!$K$2:$K$1017,"*"&$A32&"*") -> 19 | F32: =COUNTIFS('Config Baseline'!$C$2:$C$1017,"*("&F$31&")",'Config Baseline'!$K$2:$K$1017,"*"&$A32&"*") -> 46 | G32: =COUNTIFS('Config Baseline'!$C$2:$C$1017,"*("&G$31&")",'Config Baseline'!$K$2:$K$1017,"*"&$A32&"*") -> 7 | H32: =COUNTIFS('Config Baseline'!$C$2:$C$1017,"*("&H$31&")",'Config Baseline'!$K$2:$K$1017,"*"&$A32&"*") -> 37 | I32: =COUNTIFS('Config Baseline'!$C$2:$C$1017,"*("&I$31&")",'Config Baseline'!$K$2:$K$1017,"*"&$A32&"*") -> 16 | ... U32: =COUNTIFS('Config Baseline'!$C$2:$C$1017,"*("&U$31&")",'Config Baseline'!$K$2:$K$1017,"*"&$A32&"*") -> 4 | V32: =SUM(B32:U32) -> 413
A33: Cloud | B33: =COUNTIFS('Config Baseline'!$C$2:$C$1017,"*("&B$31&")",'Config Baseline'!$K$2:$K$1017,"*"&$A33&"*") -> 95 | C33: =COUNTIFS('Config Baseline'!$C$2:$C$1017,"*("&C$31&")",'Config Baseline'!$K$2:$K$1017,"*"&$A33&"*") -> 0 | D33: =COUNTIFS('Config Baseline'!$C$2:$C$1017,"*("&D$31&")",'Config Baseline'!$K$2:$K$1017,"*"&$A33&"*") -> 40 | E33: =COUNTIFS('Config Baseline'!$C$2:$C$1017,"*("&E$31&")",'Config Baseline'!$K$2:$K$1017,"*"&$A33&"*") -> 21 | F33: =COUNTIFS('Config Baseline'!$C$2:$C$1017,"*("&F$31&")",'Config Baseline'!$K$2:$K$1017,"*"&$A33&"*") -> 49 | G33: =COUNTIFS('Config Baseline'!$C$2:$C$1017,"*("&G$31&")",'Config Baseline'!$K$2:$K$1017,"*"&$A33&"*") -> 36 | H33: =COUNTIFS('Config Baseline'!$C$2:$C$1017,"*("&H$31&")",'Config Baseline'!$K$2:$K$1017,"*"&$A33&"*") -> 52 | I33: =COUNTIFS('Config Baseline'!$C$2:$C$1017,"*("&I$31&")",'Config Baseline'!$K$2:$K$1017,"*"&$A33&"*") -> 26 | ... U33: =COUNTIFS('Config Baseline'!$C$2:$C$1017,"*("&U$31&")",'Config Baseline'!$K$2:$K$1017,"*"&$A33&"*") -> 12 | V33: =SUM(B33:U33) -> 596
A34: Identity | B34: =COUNTIFS('Config Baseline'!$C$2:$C$1017,"*("&B$31&")",'Config Baseline'!$K$2:$K$1017,"*"&$A34&"*") -> 61 | C34: =COUNTIFS('Config Baseline'!$C$2:$C$1017,"*("&C$31&")",'Config Baseline'!$K$2:$K$1017,"*"&$A34&"*") -> 0 | D34: =COUNTIFS('Config Baseline'!$C$2:$C$1017,"*("&D$31&")",'Config Baseline'!$K$2:$K$1017,"*"&$A34&"*") -> 0 | E34: =COUNTIFS('Config Baseline'!$C$2:$C$1017,"*("&E$31&")",'Config Baseline'!$K$2:$K$1017,"*"&$A34&"*") -> 0 | F34: =COUNTIFS('Config Baseline'!$C$2:$C$1017,"*("&F$31&")",'Config Baseline'!$K$2:$K$1017,"*"&$A34&"*") -> 0 | G34: =COUNTIFS('Config Baseline'!$C$2:$C$1017,"*("&G$31&")",'Config Baseline'!$K$2:$K$1017,"*"&$A34&"*") -> 0 | H34: =COUNTIFS('Config Baseline'!$C$2:$C$1017,"*("&H$31&")",'Config Baseline'!$K$2:$K$1017,"*"&$A34&"*") -> 54 | I34: =COUNTIFS('Config Baseline'!$C$2:$C$1017,"*("&I$31&")",'Config Baseline'!$K$2:$K$1017,"*"&$A34&"*") -> 0 | ... U34: =COUNTIFS('Config Baseline'!$C$2:$C$1017,"*("&U$31&")",'Config Baseline'!$K$2:$K$1017,"*"&$A34&"*") -> 0 | V34: =SUM(B34:U34) -> 119
A35: Monitoring | B35: =COUNTIFS('Config Baseline'!$C$2:$C$1017,"*("&B$31&")",'Config Baseline'!$K$2:$K$1017,"*"&$A35&"*") -> 0 | C35: =COUNTIFS('Config Baseline'!$C$2:$C$1017,"*("&C$31&")",'Config Baseline'!$K$2:$K$1017,"*"&$A35&"*") -> 0 | D35: =COUNTIFS('Config Baseline'!$C$2:$C$1017,"*("&D$31&")",'Config Baseline'!$K$2:$K$1017,"*"&$A35&"*") -> 50 | E35: =COUNTIFS('Config Baseline'!$C$2:$C$1017,"*("&E$31&")",'Config Baseline'!$K$2:$K$1017,"*"&$A35&"*") -> 6 | F35: =COUNTIFS('Config Baseline'!$C$2:$C$1017,"*("&F$31&")",'Config Baseline'!$K$2:$K$1017,"*"&$A35&"*") -> 0 | G35: =COUNTIFS('Config Baseline'!$C$2:$C$1017,"*("&G$31&")",'Config Baseline'!$K$2:$K$1017,"*"&$A35&"*") -> 0 | H35: =COUNTIFS('Config Baseline'!$C$2:$C$1017,"*("&H$31&")",'Config Baseline'!$K$2:$K$1017,"*"&$A35&"*") -> 0 | I35: =COUNTIFS('Config Baseline'!$C$2:$C$1017,"*("&I$31&")",'Config Baseline'!$K$2:$K$1017,"*"&$A35&"*") -> 18 | ... U35: =COUNTIFS('Config Baseline'!$C$2:$C$1017,"*("&U$31&")",'Config Baseline'!$K$2:$K$1017,"*"&$A35&"*") -> 0 | V35: =SUM(B35:U35) -> 100
A36: Database | B36: =COUNTIFS('Config Baseline'!$C$2:$C$1017,"*("&B$31&")",'Config Baseline'!$K$2:$K$1017,"*"&$A36&"*") -> 42 | C36: =COUNTIFS('Config Baseline'!$C$2:$C$1017,"*("&C$31&")",'Config Baseline'!$K$2:$K$1017,"*"&$A36&"*") -> 0 | D36: =COUNTIFS('Config Baseline'!$C$2:$C$1017,"*("&D$31&")",'Config Baseline'!$K$2:$K$1017,"*"&$A36&"*") -> 0 | E36: =COUNTIFS('Config Baseline'!$C$2:$C$1017,"*("&E$31&")",'Config Baseline'!$K$2:$K$1017,"*"&$A36&"*") -> 0 | F36: =COUNTIFS('Config Baseline'!$C$2:$C$1017,"*("&F$31&")",'Config Baseline'!$K$2:$K$1017,"*"&$A36&"*") -> 10 | G36: =COUNTIFS('Config Baseline'!$C$2:$C$1017,"*("&G$31&")",'Config Baseline'!$K$2:$K$1017,"*"&$A36&"*") -> 12 | H36: =COUNTIFS('Config Baseline'!$C$2:$C$1017,"*("&H$31&")",'Config Baseline'!$K$2:$K$1017,"*"&$A36&"*") -> 16 | I36: =COUNTIFS('Config Baseline'!$C$2:$C$1017,"*("&I$31&")",'Config Baseline'!$K$2:$K$1017,"*"&$A36&"*") -> 0 | ... U36: =COUNTIFS('Config Baseline'!$C$2:$C$1017,"*("&U$31&")",'Config Baseline'!$K$2:$K$1017,"*"&$A36&"*") -> 0 | V36: =SUM(B36:U36) -> 115
A37: Application | B37: =COUNTIFS('Config Baseline'!$C$2:$C$1017,"*("&B$31&")",'Config Baseline'!$K$2:$K$1017,"*"&$A37&"*") -> 63 | C37: =COUNTIFS('Config Baseline'!$C$2:$C$1017,"*("&C$31&")",'Config Baseline'!$K$2:$K$1017,"*"&$A37&"*") -> 0 | D37: =COUNTIFS('Config Baseline'!$C$2:$C$1017,"*("&D$31&")",'Config Baseline'!$K$2:$K$1017,"*"&$A37&"*") -> 17 | E37: =COUNTIFS('Config Baseline'!$C$2:$C$1017,"*("&E$31&")",'Config Baseline'!$K$2:$K$1017,"*"&$A37&"*") -> 6 | F37: =COUNTIFS('Config Baseline'!$C$2:$C$1017,"*("&F$31&")",'Config Baseline'!$K$2:$K$1017,"*"&$A37&"*") -> 54 | G37: =COUNTIFS('Config Baseline'!$C$2:$C$1017,"*("&G$31&")",'Config Baseline'!$K$2:$K$1017,"*"&$A37&"*") -> 20 | H37: =COUNTIFS('Config Baseline'!$C$2:$C$1017,"*("&H$31&")",'Config Baseline'!$K$2:$K$1017,"*"&$A37&"*") -> 40 | I37: =COUNTIFS('Config Baseline'!$C$2:$C$1017,"*("&I$31&")",'Config Baseline'!$K$2:$K$1017,"*"&$A37&"*") -> 0 | ... U37: =COUNTIFS('Config Baseline'!$C$2:$C$1017,"*("&U$31&")",'Config Baseline'!$K$2:$K$1017,"*"&$A37&"*") -> 0 | V37: =SUM(B37:U37) -> 484
A38: Backup | B38: =COUNTIFS('Config Baseline'!$C$2:$C$1017,"*("&B$31&")",'Config Baseline'!$K$2:$K$1017,"*"&$A38&"*") -> 0 | C38: =COUNTIFS('Config Baseline'!$C$2:$C$1017,"*("&C$31&")",'Config Baseline'!$K$2:$K$1017,"*"&$A38&"*") -> 0 | D38: =COUNTIFS('Config Baseline'!$C$2:$C$1017,"*("&D$31&")",'Config Baseline'!$K$2:$K$1017,"*"&$A38&"*") -> 0 | E38: =COUNTIFS('Config Baseline'!$C$2:$C$1017,"*("&E$31&")",'Config Baseline'!$K$2:$K$1017,"*"&$A38&"*") -> 0 | F38: =COUNTIFS('Config Baseline'!$C$2:$C$1017,"*("&F$31&")",'Config Baseline'!$K$2:$K$1017,"*"&$A38&"*") -> 0 | G38: =COUNTIFS('Config Baseline'!$C$2:$C$1017,"*("&G$31&")",'Config Baseline'!$K$2:$K$1017,"*"&$A38&"*") -> 33 | H38: =COUNTIFS('Config Baseline'!$C$2:$C$1017,"*("&H$31&")",'Config Baseline'!$K$2:$K$1017,"*"&$A38&"*") -> 0 | I38: =COUNTIFS('Config Baseline'!$C$2:$C$1017,"*("&I$31&")",'Config Baseline'!$K$2:$K$1017,"*"&$A38&"*") -> 0 | ... U38: =COUNTIFS('Config Baseline'!$C$2:$C$1017,"*("&U$31&")",'Config Baseline'!$K$2:$K$1017,"*"&$A38&"*") -> 0 | V38: =SUM(B38:U38) -> 33
A39: Governance | B39: =COUNTIFS('Config Baseline'!$C$2:$C$1017,"*("&B$31&")",'Config Baseline'!$K$2:$K$1017,"*"&$A39&"*") -> 1 | C39: =COUNTIFS('Config Baseline'!$C$2:$C$1017,"*("&C$31&")",'Config Baseline'!$K$2:$K$1017,"*"&$A39&"*") -> 16 | D39: =COUNTIFS('Config Baseline'!$C$2:$C$1017,"*("&D$31&")",'Config Baseline'!$K$2:$K$1017,"*"&$A39&"*") -> 10 | E39: =COUNTIFS('Config Baseline'!$C$2:$C$1017,"*("&E$31&")",'Config Baseline'!$K$2:$K$1017,"*"&$A39&"*") -> 14 | F39: =COUNTIFS('Config Baseline'!$C$2:$C$1017,"*("&F$31&")",'Config Baseline'!$K$2:$K$1017,"*"&$A39&"*") -> 1 | G39: =COUNTIFS('Config Baseline'!$C$2:$C$1017,"*("&G$31&")",'Config Baseline'!$K$2:$K$1017,"*"&$A39&"*") -> 1 | H39: =COUNTIFS('Config Baseline'!$C$2:$C$1017,"*("&H$31&")",'Config Baseline'!$K$2:$K$1017,"*"&$A39&"*") -> 1 | I39: =COUNTIFS('Config Baseline'!$C$2:$C$1017,"*("&I$31&")",'Config Baseline'!$K$2:$K$1017,"*"&$A39&"*") -> 37 | ... U39: =COUNTIFS('Config Baseline'!$C$2:$C$1017,"*("&U$31&")",'Config Baseline'!$K$2:$K$1017,"*"&$A39&"*") -> 1 | V39: =SUM(B39:U39) -> 179
A40: Physical | B40: =COUNTIFS('Config Baseline'!$C$2:$C$1017,"*("&B$31&")",'Config Baseline'!$K$2:$K$1017,"*"&$A40&"*") -> 0 | C40: =COUNTIFS('Config Baseline'!$C$2:$C$1017,"*("&C$31&")",'Config Baseline'!$K$2:$K$1017,"*"&$A40&"*") -> 0 | D40: =COUNTIFS('Config Baseline'!$C$2:$C$1017,"*("&D$31&")",'Config Baseline'!$K$2:$K$1017,"*"&$A40&"*") -> 0 | E40: =COUNTIFS('Config Baseline'!$C$2:$C$1017,"*("&E$31&")",'Config Baseline'!$K$2:$K$1017,"*"&$A40&"*") -> 0 | F40: =COUNTIFS('Config Baseline'!$C$2:$C$1017,"*("&F$31&")",'Config Baseline'!$K$2:$K$1017,"*"&$A40&"*") -> 0 | G40: =COUNTIFS('Config Baseline'!$C$2:$C$1017,"*("&G$31&")",'Config Baseline'!$K$2:$K$1017,"*"&$A40&"*") -> 0 | H40: =COUNTIFS('Config Baseline'!$C$2:$C$1017,"*("&H$31&")",'Config Baseline'!$K$2:$K$1017,"*"&$A40&"*") -> 0 | I40: =COUNTIFS('Config Baseline'!$C$2:$C$1017,"*("&I$31&")",'Config Baseline'!$K$2:$K$1017,"*"&$A40&"*") -> 0 | ... U40: =COUNTIFS('Config Baseline'!$C$2:$C$1017,"*("&U$31&")",'Config Baseline'!$K$2:$K$1017,"*"&$A40&"*") -> 7 | V40: =SUM(B40:U40) -> 103
A41: Third Party | B41: =COUNTIFS('Config Baseline'!$C$2:$C$1017,"*("&B$31&")",'Config Baseline'!$K$2:$K$1017,"*"&$A41&"*") -> 0 | C41: =COUNTIFS('Config Baseline'!$C$2:$C$1017,"*("&C$31&")",'Config Baseline'!$K$2:$K$1017,"*"&$A41&"*") -> 0 | D41: =COUNTIFS('Config Baseline'!$C$2:$C$1017,"*("&D$31&")",'Config Baseline'!$K$2:$K$1017,"*"&$A41&"*") -> 0 | E41: =COUNTIFS('Config Baseline'!$C$2:$C$1017,"*("&E$31&")",'Config Baseline'!$K$2:$K$1017,"*"&$A41&"*") -> 0 | F41: =COUNTIFS('Config Baseline'!$C$2:$C$1017,"*("&F$31&")",'Config Baseline'!$K$2:$K$1017,"*"&$A41&"*") -> 0 | G41: =COUNTIFS('Config Baseline'!$C$2:$C$1017,"*("&G$31&")",'Config Baseline'!$K$2:$K$1017,"*"&$A41&"*") -> 0 | H41: =COUNTIFS('Config Baseline'!$C$2:$C$1017,"*("&H$31&")",'Config Baseline'!$K$2:$K$1017,"*"&$A41&"*") -> 0 | I41: =COUNTIFS('Config Baseline'!$C$2:$C$1017,"*("&I$31&")",'Config Baseline'!$K$2:$K$1017,"*"&$A41&"*") -> 0 | ... U41: =COUNTIFS('Config Baseline'!$C$2:$C$1017,"*("&U$31&")",'Config Baseline'!$K$2:$K$1017,"*"&$A41&"*") -> 23 | V41: =SUM(B41:U41) -> 32
A44: Base controls only, by domain and family
A45: IT Domain | B45: AC | C45: AT | D45: AU | E45: CA | F45: CM | G45: CP | H45: IA | I45: IR | J45: MA | K45: MP | L45: PE | M45: PL | N45: PM | O45: PS | P45: PT | Q45: RA | R45: SA | S45: SC | T45: SI | U45: SR | V45: Total
A46: Network | B46: =SUMPRODUCT(ISNUMBER(SEARCH("("&B$45&")",'Config Baseline'!$C$2:$C$1017))*ISNUMBER(SEARCH($A46,'Config Baseline'!$K$2:$K$1017))*ISERROR(SEARCH("(",'Config Baseline'!$B$2:$B$1017))) -> 13 | C46: =SUMPRODUCT(ISNUMBER(SEARCH("("&C$45&")",'Config Baseline'!$C$2:$C$1017))*ISNUMBER(SEARCH($A46,'Config Baseline'!$K$2:$K$1017))*ISERROR(SEARCH("(",'Config Baseline'!$B$2:$B$1017))) -> 0 | D46: =SUMPRODUCT(ISNUMBER(SEARCH("("&D$45&")",'Config Baseline'!$C$2:$C$1017))*ISNUMBER(SEARCH($A46,'Config Baseline'!$K$2:$K$1017))*ISERROR(SEARCH("(",'Config Baseline'!$B$2:$B$1017))) -> 9 | E46: =SUMPRODUCT(ISNUMBER(SEARCH("("&E$45&")",'Config Baseline'!$C$2:$C$1017))*ISNUMBER(SEARCH($A46,'Config Baseline'!$K$2:$K$1017))*ISERROR(SEARCH("(",'Config Baseline'!$B$2:$B$1017))) -> 5 | F46: =SUMPRODUCT(ISNUMBER(SEARCH("("&F$45&")",'Config Baseline'!$C$2:$C$1017))*ISNUMBER(SEARCH($A46,'Config Baseline'!$K$2:$K$1017))*ISERROR(SEARCH("(",'Config Baseline'!$B$2:$B$1017))) -> 8 | G46: =SUMPRODUCT(ISNUMBER(SEARCH("("&G$45&")",'Config Baseline'!$C$2:$C$1017))*ISNUMBER(SEARCH($A46,'Config Baseline'!$K$2:$K$1017))*ISERROR(SEARCH("(",'Config Baseline'!$B$2:$B$1017))) -> 2 | H46: =SUMPRODUCT(ISNUMBER(SEARCH("("&H$45&")",'Config Baseline'!$C$2:$C$1017))*ISNUMBER(SEARCH($A46,'Config Baseline'!$K$2:$K$1017))*ISERROR(SEARCH("(",'Config Baseline'!$B$2:$B$1017))) -> 5 | I46: =SUMPRODUCT(ISNUMBER(SEARCH("("&I$45&")",'Config Baseline'!$C$2:$C$1017))*ISNUMBER(SEARCH($A46,'Config Baseline'!$K$2:$K$1017))*ISERROR(SEARCH("(",'Config Baseline'!$B$2:$B$1017))) -> 1 | ... U46: =SUMPRODUCT(ISNUMBER(SEARCH("("&U$45&")",'Config Baseline'!$C$2:$C$1017))*ISNUMBER(SEARCH($A46,'Config Baseline'!$K$2:$K$1017))*ISERROR(SEARCH("(",'Config Baseline'!$B$2:$B$1017))) -> 1 | V46: =SUM(B46:U46) -> 76
...

Sheet Baseline Summary
A1: Configuration Baseline Summary - control families and control IDs used by each topic
A2: How to read: "Control families" = number of NIST SP 800-53 families (AC, AU, CA ...) that have at least one row in the topic baseline sheet. "Control IDs" = number of rows (base controls plus enhancements) in that sheet. All values are formulas that read the topic sheets. "Tagged in master" comes from Domain Summary (every control tagged to the domain in Config Baseline) so you can see how much of it each baseline keeps. Network and Cloud are the existing sheets; the other eight topics use the same core-item approach (only rows tagged to that domain, similar controls consolidated).
A4: Topic (IT Domain) | B4: Baseline sheet | C4: Control families used | D4: Control IDs used | E4: Level 1 | F4: Level 2 | G4: Level 3 | H4: Families tagged in master | I4: IDs tagged in master | J4: IDs used as % of tagged
A5: Network | B5: Network Config Baseline | C5: =COUNTIF('Network Config Baseline'!$B$15:$B$22,">0") -> 8 | D5: =COUNTA('Network Config Baseline'!$B$26:$B$95) -> 70 | E5: =COUNTIF('Network Config Baseline'!$I$26:$I$95,"Level 1*") -> 43 | F5: =COUNTIF('Network Config Baseline'!$I$26:$I$95,"Level 2*") -> 27 | G5: =COUNTIF('Network Config Baseline'!$I$26:$I$95,"Level 3*") -> 0 | H5: ='Domain Summary'!B4 -> 14 | I5: ='Domain Summary'!D4 -> 413 | J5: =IF(I5=0,0,D5/I5) -> 0.16949153
A6: Cloud | B6: Cloud Config Baseline | C6: =COUNTIF('Cloud Config Baseline'!$B$16:$B$26,">0") -> 11 | D6: =COUNTA('Cloud Config Baseline'!$B$30:$B$313) -> 284 | E6: =COUNTIF('Cloud Config Baseline'!$I$30:$I$313,"Level 1*") -> 69 | F6: =COUNTIF('Cloud Config Baseline'!$I$30:$I$313,"Level 2*") -> 121 | G6: =COUNTIF('Cloud Config Baseline'!$I$30:$I$313,"Level 3*") -> 94 | H6: ='Domain Summary'!B5 -> 15 | I6: ='Domain Summary'!D5 -> 596 | J6: =IF(I6=0,0,D6/I6) -> 0.47651007
A7: Identity | B7: Identity Config Baseline | C7: =COUNTIF('Identity Config Baseline'!$B$15:$B$17,">0") -> 3 | D7: =COUNTA('Identity Config Baseline'!$B$21:$B$68) -> 48 | E7: =COUNTIF('Identity Config Baseline'!$I$21:$I$68,"Level 1*") -> 14 | F7: =COUNTIF('Identity Config Baseline'!$I$21:$I$68,"Level 2*") -> 34 | G7: =COUNTIF('Identity Config Baseline'!$I$21:$I$68,"Level 3*") -> 0 | H7: ='Domain Summary'!B6 -> 3 | I7: ='Domain Summary'!D6 -> 119 | J7: =IF(I7=0,0,D7/I7) -> 0.40336134
A8: Monitoring | B8: Monitoring Config Baseline | C8: =COUNTIF('Monitoring Config Baseline'!$B$15:$B$19,">0") -> 5 | D8: =COUNTA('Monitoring Config Baseline'!$B$23:$B$58) -> 36 | E8: =COUNTIF('Monitoring Config Baseline'!$I$23:$I$58,"Level 1*") -> 14 | F8: =COUNTIF('Monitoring Config Baseline'!$I$23:$I$58,"Level 2*") -> 22 | G8: =COUNTIF('Monitoring Config Baseline'!$I$23:$I$58,"Level 3*") -> 0 | H8: ='Domain Summary'!B7 -> 6 | I8: ='Domain Summary'!D7 -> 100 | J8: =IF(I8=0,0,D8/I8) -> 0.36
A9: Database | B9: Database Config Baseline | C9: =COUNTIF('Database Config Baseline'!$B$15:$B$21,">0") -> 7 | D9: =COUNTA('Database Config Baseline'!$B$25:$B$66) -> 42 | E9: =COUNTIF('Database Config Baseline'!$I$25:$I$66,"Level 1*") -> 21 | F9: =COUNTIF('Database Config Baseline'!$I$25:$I$66,"Level 2*") -> 21 | G9: =COUNTIF('Database Config Baseline'!$I$25:$I$66,"Level 3*") -> 0 | H9: ='Domain Summary'!B8 -> 7 | I9: ='Domain Summary'!D8 -> 115 | J9: =IF(I9=0,0,D9/I9) -> 0.36521739
A10: Application | B10: Application Config Baseline | C10: =COUNTIF('Application Config Baseline'!$B$15:$B$24,">0") -> 10 | D10: =COUNTA('Application Config Baseline'!$B$28:$B$117) -> 90 | E10: =COUNTIF('Application Config Baseline'!$I$28:$I$117,"Level 1*") -> 39 | F10: =COUNTIF('Application Config Baseline'!$I$28:$I$117,"Level 2*") -> 34 | G10: =COUNTIF('Application Config Baseline'!$I$28:$I$117,"Level 3*") -> 17 | H10: ='Domain Summary'!B9 -> 12 | I10: ='Domain Summary'!D9 -> 484 | J10: =IF(I10=0,0,D10/I10) -> 0.18595041
A11: Backup | B11: Backup Config Baseline | C11: =COUNTIF('Backup Config Baseline'!$B$15:$B$15,">0") -> 1 | D11: =COUNTA('Backup Config Baseline'!$B$19:$B$33) -> 15 | E11: =COUNTIF('Backup Config Baseline'!$I$19:$I$33,"Level 1*") -> 3 | F11: =COUNTIF('Backup Config Baseline'!$I$19:$I$33,"Level 2*") -> 7 | G11: =COUNTIF('Backup Config Baseline'!$I$19:$I$33,"Level 3*") -> 5 | H11: ='Domain Summary'!B10 -> 1 | I11: ='Domain Summary'!D10 -> 33 | J11: =IF(I11=0,0,D11/I11) -> 0.45454545
A12: Governance | B12: Governance Config Baseline | C12: =COUNTIF('Governance Config Baseline'!$B$15:$B$33,">0") -> 19 | D12: =COUNTA('Governance Config Baseline'!$B$37:$B$78) -> 42 | E12: =COUNTIF('Governance Config Baseline'!$I$37:$I$78,"Level 1*") -> 0 | F12: =COUNTIF('Governance Config Baseline'!$I$37:$I$78,"Level 2*") -> 3 | G12: =COUNTIF('Governance Config Baseline'!$I$37:$I$78,"Level 3*") -> 39 | H12: ='Domain Summary'!B11 -> 19 | I12: ='Domain Summary'!D11 -> 179 | J12: =IF(I12=0,0,D12/I12) -> 0.23463687
A13: Physical | B13: Physical Config Baseline | C13: =COUNTIF('Physical Config Baseline'!$B$15:$B$18,">0") -> 4 | D13: =COUNTA('Physical Config Baseline'!$B$22:$B$47) -> 26 | E13: =COUNTIF('Physical Config Baseline'!$I$22:$I$47,"Level 1*") -> 3 | F13: =COUNTIF('Physical Config Baseline'!$I$22:$I$47,"Level 2*") -> 7 | G13: =COUNTIF('Physical Config Baseline'!$I$22:$I$47,"Level 3*") -> 16 | H13: ='Domain Summary'!B12 -> 4 | I13: ='Domain Summary'!D12 -> 103 | J13: =IF(I13=0,0,D13/I13) -> 0.25242718
A14: Third Party | B14: Third Party Config Baseline | C14: =COUNTIF('Third Party Config Baseline'!$B$15:$B$16,">0") -> 2 | D14: =COUNTA('Third Party Config Baseline'!$B$20:$B$33) -> 14 | E14: =COUNTIF('Third Party Config Baseline'!$I$20:$I$33,"Level 1*") -> 0 | F14: =COUNTIF('Third Party Config Baseline'!$I$20:$I$33,"Level 2*") -> 3 | G14: =COUNTIF('Third Party Config Baseline'!$I$20:$I$33,"Level 3*") -> 11 | H14: ='Domain Summary'!B13 -> 2 | I14: ='Domain Summary'!D13 -> 32 | J14: =IF(I14=0,0,D14/I14) -> 0.4375
A15: Total (topics overlap, so IDs add up) | D15: =SUM(D5:D14) -> 667 | E15: =SUM(E5:E14) -> 206 | F15: =SUM(F5:F14) -> 279 | G15: =SUM(G5:G14) -> 182 | I15: =SUM(I5:I14) -> 2174 | J15: =IF(I15=0,0,D15/I15) -> 0.30680773
A16: Unique control IDs across all topic sheets | D16: =SUMPRODUCT(1/COUNTIF(Helper!$A$2:$A$668,Helper!$A$2:$A$668)) -> 402
A17: Note: a control ID can belong to several topics (for example AC-06 is in Identity, Database, Application and Cloud), so the Total row counts it once per topic and the row above counts it once overall.

Sheet Cloud Config Baseline
A1: Cloud Configuration Baseline (NIST SP 800-53 Rev. 5 - core configuration items)
A2: Purpose: this sheet turns the NIST SP 800-53 Rev. 5 controls into the Cloud Configuration Baseline. It lists the settings that administrators must configure, implement, install or enable in a cloud environment (IaaS, PaaS and SaaS tenant configuration) so that every account, subscription or project meets the same security baseline.
A3: Scope (v3.1 update): the baseline covers the 11 families AC, AU, CA, CM, CP, IA, IR, RA, SA, SC, SI and now contains every control ID that Bitdefender GravityZone evaluated for this organisation (126 IDs, all present) plus the control IDs of the Cloud Baseline Groups sheet (164 representative IDs; 4 of them - AC-12(2), AC-12(3), AC-19(4), SA-15(13) - and SC-7(16) from Bitdefender are not in the Config Baseline master and were added with analyst-assigned Level and CSF mapping). Governance and process controls (policy -1 controls, training, testing, assessment) are now listed as Level 3 rows so the baseline can be compared one-to-one with those files.
A4: Selection principle: original rows are kept unchanged. Rows added from Bitdefender and Cloud Baseline Groups are marked in column M (Source of Row). Column K gives the Cloud Baseline Groups domain (9 domains), column L the Bitdefender result (PASS / FAIL / NOT EVALUATED) and column N the related control IDs that the Groups sheet folds into the same practice. Use the Cloud Coverage Check sheet to verify coverage.
A5: Supply chain (SR): SR controls are contractual and process based (supplier assessment, notification agreements) with no direct cloud setting, so they are not listed. The technical side of cloud provider risk is covered by SA-9, SA-9(5) and SA-9(6).
